Workbook

Sheet Tabel Gaji Guru Tetap
C1: 1300000 | D1: 1400000 | E1: 1350000 | F1: 1450000 | G1: 1400000 | H1: 1500000
A2: Tabel Gaji Pokok Guru Tetap YPWI Luwu Timur
A4: Jenjang | B4: Konversi | C4: Masa Kerja/Pendidikan
C5: 2 tahun | E5: 3 - 4 Tahun | G5: 5 - 6 Tahun | I5: 7 - 8 Tahun | K5: 9-10 Tahun
C6: SMA | D6: S1 | E6: SMA | F6: S1 | G6: SMA | H6: S1 | I6: SMA | J6: S1 | K6: SMA | L6: S1
A7: TK | B7: 50000 | C7: 500000 | D7: =C7+400000 -> 900000 | E7: =C7+$B7 -> 550000 | F7: =D7+$B7 -> 950000 | G7: =E7+$B7 -> 600000 | H7: =F7+$B7 -> 1000000 | I7: =G7+$B7 -> 650000 | J7: =H7+$B7 -> 1050000 | K7: =I7+$B7 -> 700000 | L7: =J7+$B7 -> 1100000
A8: SD | B8: 50000 | C8: 800000 | D8: =C8+1000000 -> 1800000 | E8: =C8+$B8 -> 850000 | F8: =D8+$B8 -> 1850000 | G8: =E8+$B8 -> 900000 | H8: =F8+$B8 -> 1900000 | I8: =G8+$B8 -> 950000 | J8: =H8+$B8 -> 1950000 | K8: =I8+$B8 -> 1000000 | L8: =J8+$B8 -> 2000000
A9: SMP | B9: 50000 | C9: 500000 | D9: =C9+400000 -> 900000 | E9: =C9+$B9 -> 550000 | F9: =D9+$B9 -> 950000 | G9: =E9+$B9 -> 600000 | H9: =F9+$B9 -> 1000000 | I9: =G9+$B9 -> 650000 | J9: =H9+$B9 -> 1050000 | K9: =I9+$B9 -> 700000 | L9: =J9+$B9 -> 1100000
A10: SMA/PONPES | B10: 50000 | C10: 500000 | D10: =C10+400000 -> 900000 | E10: =C10+$B10 -> 550000 | F10: =D10+$B10 -> 950000 | G10: =E10+$B10 -> 600000 | H10: =F10+$B10 -> 1000000 | I10: =G10+$B10 -> 650000 | J10: =H10+$B10 -> 1050000 | K10: =I10+$B10 -> 700000 | L10: =J10+$B10 -> 1100000
A12: Jenjang | B12: Konversi | C12: Masa Kerja/Pendidikan
C13: 11 - 12 Tahun | E13: 13-14 Tahun | G13: 15-16 Tahun | I13: 17-18 tahun | K13: 19-20 tahun
C14: SMA | D14: S1 | E14: SMA | F14: S1 | G14: SMA | H14: S1 | I14: SMA | J14: S1 | K14: SMA | L14: S1
A15: TK | B15: 50000 | C15: =$K7+$B15 -> 750000 | D15: =$L7+$B15 -> 1150000 | E15: =C15+$B15 -> 800000 | F15: =D15+$B15 -> 1200000 | G15: =E15+$B15 -> 850000 | H15: =F15+$B15 -> 1250000 | I15: =G15+$B15 -> 900000 | J15: =H15+$B15 -> 1300000 | K15: =I15+$B15 -> 950000 | L15: =J15+$B15 -> 1350000
A16: SD | B16: 50000 | C16: =$K8+$B16 -> 1050000 | D16: =$L8+$B16 -> 2050000 | E16: =C16+$B16 -> 1100000 | F16: =D16+$B16 -> 2100000 | G16: =E16+$B16 -> 1150000 | H16: =F16+$B16 -> 2150000 | I16: =G16+$B16 -> 1200000 | J16: =H16+$B16 -> 2200000 | K16: =I16+$B16 -> 1250000 | L16: =J16+$B16 -> 2250000
A17: SMP | B17: 50000 | C17: =$K9+$B17 -> 750000 | D17: =$L9+$B17 -> 1150000 | E17: =C17+$B17 -> 800000 | F17: =D17+$B17 -> 1200000 | G17: =E17+$B17 -> 850000 | H17: =F17+$B17 -> 1250000 | I17: =G17+$B17 -> 900000 | J17: =H17+$B17 -> 1300000 | K17: =I17+$B17 -> 950000 | L17: =J17+$B17 -> 1350000
A18: SMA/PONPES | B18: 50000 | C18: =$K10+$B18 -> 750000 | D18: =$L10+$B18 -> 1150000 | E18: =C18+$B18 -> 800000 | F18: =D18+$B18 -> 1200000 | G18: =E18+$B18 -> 850000 | H18: =F18+$B18 -> 1250000 | I18: =G18+$B18 -> 900000 | J18: =H18+$B18 -> 1300000 | K18: =I18+$B18 -> 950000 | L18: =J18+$B18 -> 1350000
J20: Ketua YPWI Luwu Timur
J23: Sudarsono, S.Ag

Sheet Tabel Gaji Kontrak
B1: 1 | D1: 3
B2: SMA | C2: S1 | D2: SMA | E2: S1
A3: TK | B3: 1000000 | C3: 1050000 | D3: 1050000 | E3: 1100000
A4: SD | B4: 1300000 | C4: 1400000 | D4: 1350000 | E4: 1450000
A5: SMP | B5: 1300000 | C5: 1400000 | D5: 1350000 | E5: 1450000
A6: Tabel Gaji Pokok Guru Kontrak YPWI Luwu Timur
A8: Jenjang | B8: Masa Kerja/Pendidikan
B9: ≤ 1 Tahun | D9: 1 - 3 Tahun
B10: SMA | C10: S1 | D10: SMA | E10: S1
A11: TK | B11: 300000 | C11: 500000 | D11: =B11+50000 -> 350000 | E11: =C11+50000 -> 550000
A12: SD | B12: 300000 | C12: 500000 | D12: =B12+50000 -> 350000 | E12: =C12+50000 -> 550000
A13: SMP | B13: 300000 | C13: 500000 | D13: =B13+50000 -> 350000 | E13: =C13+50000 -> 550000
A14: SMA/PONPES | B14: 300000 | C14: 500000 | D14: =B14+50000 -> 350000 | E14: =C14+50000 -> 550000

Sheet Data Base TK Malili
A1: DATA BASE TENAGA PEGAWAI
A2: YAYASAN PENDIDIKAN
A3: UNIT TKIT
A4: TAHUN AJARAN 2026-2027
A6: No | B6: Nama | C6: Jenis Kelamin | D6: Tanggal Masuk | E6: Today | F6: Masa Kerja | G6: Status Kepegawaian (PP/PK/PT/INVAL) | H6: Golongan Kepegawaian | I6: NUPTK | J6: Jabatan | K6: NIY | L6: Tempat Kelahiran | M6: Tanggal Lahir | N6: Usia | O6: NIK | P6: Alamat KTP | Q6: Alamat Domisili Sekarang | R6: Ijazah Terakhir | S6: Ijazah Terakhir / Jurusan / PT | T6: Status Pernikahan | U6: Nama Suami/Istri | V6: No. BPJS Kesehatan | W6: NPWP | X6: Jumlah Anak | Y6: No. Telp | AA6: Nama Murrobbi/Murobbiyah | AB6: E-Mail | AC6: Pengalaman Kerja | AD6: Pelatihan Yang telah diikuti | AE6: Skill (kemampuan) yang dimiliki | AF6: Skill (kemampuan) yang ingin ditingkatkan | AG6: Kemampuan Berbahasa Asing | AH6: Keterangan
Y7: Pribadi | Z7: Keluarga
A8: 1 | B8: SITI FARIDAH,S.Pd,Paud.,Gr | C8: PR | D8: 42552 | E8: =TODAY() -> 46244 | F8: =DATEDIF(D8,E8,"y")&" "&"Tahun"&" "&DATEDIF(D8,E8,"ym")&" "&"Bulan"&" "&DATEDIF(D8,E8,"md")&" "&"Hari" -> 10 Tahun 1 Bulan 9 Hari | G8: PT | J8: Kepsek | K8: 1802199006200805001 | L8: Jakarta | M8: 32922 | N8: =DATEDIF(M8,E8,"y")&" "&"Tahun"&" "&DATEDIF(M8,E8,"ym")&" "&"Bulan"&" "&DATEDIF(M8,E8,"md")&" "&"Hari" -> 36 Tahun 5 Bulan 23 Hari | P8: 0 | R8: S1 | T8: Menikah | V8: - | W8: 0 | X8: 0 | AB8: 0 | AC8: 0 | AD8: 0 | AE8: 0 | AF8: 0 | AG8: 0
A9: 2 | B9: IDAYATI,S.Pd.Gr | C9: PR | D9: 44409 | E9: =TODAY() -> 46244 | F9: =DATEDIF(D9,E9,"y")&" "&"Tahun"&" "&DATEDIF(D9,E9,"ym")&" "&"Bulan"&" "&DATEDIF(D9,E9,"md")&" "&"Hari" -> 5 Tahun 0 Bulan 9 Hari | G9: PT | J9: Bendahara/Wali Kelas | K9: 1911199708202105005 | L9: Pare-pare | M9: 35753 | N9: =DATEDIF(M9,E9,"y")&" "&"Tahun"&" "&DATEDIF(M9,E9,"ym")&" "&"Bulan"&" "&DATEDIF(M9,E9,"md")&" "&"Hari" -> 28 Tahun 8 Bulan 22 Hari | P9: 0 | R9: S1 | T9: Menikah | V9: 0 | W9: 0 | X9: 1 | Z9: 0 | AB9: 0 | AC9: 0 | AD9: 0 | AE9: 0 | AF9: 0 | AG9: 0
A10: 3 | B10: NURHIDAYANTY,SE | C10: PR | D10: 44753 | E10: =TODAY() -> 46244 | F10: =DATEDIF(D10,E10,"y")&" "&"Tahun"&" "&DATEDIF(D10,E10,"ym")&" "&"Bulan"&" "&DATEDIF(D10,E10,"md")&" "&"Hari" -> 4 Tahun 0 Bulan 30 Hari | G10: PT | J10: Wali Kelas | K10: 2112199206202205006 | L10: Pangkep | M10: 33959 | N10: =DATEDIF(M10,E10,"y")&" "&"Tahun"&" "&DATEDIF(M10,E10,"ym")&" "&"Bulan"&" "&DATEDIF(M10,E10,"md")&" "&"Hari" -> 33 Tahun 7 Bulan 20 Hari | P10: 0 | R10: S1 | T10: Menikah | V10: 0 | W10: 0 | X10: 0 | Z10: 0 | AB10: 0 | AC10: 0 | AD10: 0 | AE10: 0 | AF10: 0 | AG10: 0
A11: 4 | B11: NURMIANTI | C11: PR | D11: 45483 | E11: =TODAY() -> 46244 | F11: =DATEDIF(D11,E11,"y")&" "&"Tahun"&" "&DATEDIF(D11,E11,"ym")&" "&"Bulan"&" "&DATEDIF(D11,E11,"md")&" "&"Hari" -> 2 Tahun 1 Bulan 0 Hari | G11: PT | J11: Wali Kelas | K11: 1604199207202405008 | L11: Turmandi | M11: 33710 | N11: =DATEDIF(M11,E11,"y")&" "&"Tahun"&" "&DATEDIF(M11,E11,"ym")&" "&"Bulan"&" "&DATEDIF(M11,E11,"md")&" "&"Hari" -> 34 Tahun 3 Bulan 25 Hari | P11: 0 | R11: S1 | T11: Menikah | V11: 0 | W11: 0 | X11: 2 | Z11: 0 | AB11: 0 | AC11: 0 | AD11: 0 | AE11: 0 | AF11: 0 | AG11: 0
A12: 5 | B12: FITRIANI | C12: PR | D12: 45847 | E12: =TODAY() -> 46244 | F12: =DATEDIF(D12,E12,"y")&" "&"Tahun"&" "&DATEDIF(D12,E12,"ym")&" "&"Bulan"&" "&DATEDIF(D12,E12,"md")&" "&"Hari" -> 1 Tahun 1 Bulan 1 Hari | G12: PK | J12: Wali Kelas | M12: 35279 | N12: =DATEDIF(M12,E12,"y")&" "&"Tahun"&" "&DATEDIF(M12,E12,"ym")&" "&"Bulan"&" "&DATEDIF(M12,E12,"md")&" "&"Hari" -> 30 Tahun 0 Bulan 8 Hari | P12: 0 | R12: SMA | T12: Menikah | V12: 0 | W12: 0 | X12: 1 | Z12: 0 | AB12: 0 | AC12: 0 | AD12: 0 | AE12: 0 | AF12: 0 | AG12: 0
A13: 6 | B13: NURAINI PUSPITA,S.Pdi | C13: PR | D13: 45923 | E13: =TODAY() -> 46244 | F13: =DATEDIF(D13,E13,"y")&" "&"Tahun"&" "&DATEDIF(D13,E13,"ym")&" "&"Bulan"&" "&DATEDIF(D13,E13,"md")&" "&"Hari" -> 0 Tahun 10 Bulan 18 Hari | G13: PK | J13: Wali Kelas | L13: Luwu Timur | N13: =DATEDIF(M13,E13,"y")&" "&"Tahun"&" "&DATEDIF(M13,E13,"ym")&" "&"Bulan"&" "&DATEDIF(M13,E13,"md")&" "&"Hari" -> 126 Tahun 7 Bulan 10 Hari | P13: 0 | R13: S1 | T13: Belum Menikah | V13: 0 | W13: 0 | X13: 0 | Z13: 0 | AB13: 0 | AC13: 0 | AD13: 0 | AE13: 0 | AF13: 0 | AG13: 0

Sheet TK Malili
A1: DRAFT STRUKTUR KAFALAH TK
A2: TAHUN AJARAN 2026-2027
B3: Periode 26 Juni 2026 s/d 25 Juli 2026 | AJ3: 125000
B4: TKIT INSAN RABBANI | L4: Blok Merah kena Pelanggaran
B5: =TODAY() -> 46244 | L5: Blok Kuning Cuti
A6: A. PEGAWAI TETAP YAYASAN (BERHENTI/DIBERHENTIKAN)
A7: 1 | B7: 2 | C7: 3 | D7: 4 | E7: 5 | F7: 6 | G7: 7 | H7: 8 | I7: 9 | J7: 10 | K7: 11 | L7: 12 | M7: 13 | N7: 14 | O7: 15 | P7: 16 | Q7: 17 | R7: 18 | S7: 19 | T7: 20 | U7: 21 | V7: 22 | W7: 23 | X7: 24 | Y7: 25 | Z7: 26 | AA7: 27 | AB7: 28 | AC7: 29 | AD7: 30 | AE7: 31 | AF7: 32 | AG7: 33 | AH7: 34 | AI7: 35 | AJ7: 36 | AK7: 37 | AL7: 38 | AM7: 39 | AN7: 40 | AO7: 41 | AP7: 42 | AQ7: 43 | AR7: 44 | AS7: 45 | AT7: 46 | AU7: 47 | AV7: 48 | AW7: 49
A8: NO | B8: NAMA | C8: Jabatan | D8: Kehadiran Real | E8: HARI EFEKTIF | F8: KEHADIRAN | G8: TIDAK HADIR | H8: TEPAT WAKTU DATANG | I8: TERLAMBAT | J8: TIDAK ABSEN MASUK | K8: TIDAK CEPAT PULANG | L8: CEPAT PULANG | M8: TIDAK ABSEN PULANG | N8: DURASI SIM-T & Keterlambatan Mengajar | O8: KJM | P8: Starata | Q8: LAMA MENGABDI | R8: Jumlah Pengabdian | S8: Status Pegawai | T8: PENDAPATAN WAJIB | X8: TOTAL 1 | Y8: PENDAPATAN INSENTIF | AL8: TOTAL 2 | AM8: JUMLAH PENDAPATAN (TOTAL 1, 2,) | AN8: PEMOTONGAN | AU8: JUMLAH PEMOTONGAN | AV8: NAMA | AW8: TOTAL KAFALAH YANG DITERIMA
T9: KAFALAH POKOK | U9: TUNJ. KELUARGA | Y9: TUNJ. STRUKTURAL JABATAN | Z9: TUNJ. PENGABDIAN | AA9: TUNJ. FUNGSIONAL | AE9: TOTAL TUNJ. FUNGSIONAL | AF9: TUNJ. TRANSPORTASI | AG9: TUNJ. TEPAT WAKTU DATANG | AH9: TUNJ. TIDAK CEPAT PULANG | AI9: TUNJ. KJM | AJ9: TUNJ. PRESTASI KINERJA | AK9: TUNJ. APRESIASI | AN9: PEMOTONGAN LUAR TANGGUNGAN | AO9: Persen (%) Cuti Luar Tanggungan | AP9: DURASI SIM-T | AQ9: Jumlah Pemotongan SIM-T | AR9: Ta`awun | AS9: PINJAMAN | AT9: Predikat Kinerja
U10: ISTRI | V10: JML ANAK | W10: ANAK | AA10: 1 | AB10: 2 | AC10: 3 | AD10: 4
A11: 1 | B11: ='Data Base TK Malili'!B8 -> SITI FARIDAH,S.Pd,Paud.,Gr | C11: ='Data Base TK Malili'!J8 -> Kepsek | D11: =F11+I11 -> 23 | E11: 24 | F11: =E11-G11-I11 -> 22 | G11: 1 | H11: =E11-G11-I11-J11 -> 21 | I11: 1 | J11: 1 | K11: =E11-G11-L11-M11 -> 21 | L11: 1 | M11: 1 | N11: 0 | P11: ='Data Base TK Malili'!R8 -> S1 | Q11: ='Data Base TK Malili'!F8 -> 10 Tahun 1 Bulan 9 Hari | R11: 10 | S11: ='Data Base TK Malili'!G8 -> PT | T11: 1100000 | V11: ='Data Base TK Malili'!X8 -> 0 | W11: =V11*20000 -> 0 | X11: =T11+U11+W11 -> 1100000 | Y11: 500000 | Z11: 150000 | AA11: 100000 | AE11: =SUM(AA11:AD11) -> 100000 | AF11: =F11*7000 -> 154000 | AG11: =H11*5000 -> 105000 | AH11: =K11*5000 -> 105000 | AI11: =O11*5000 -> 0 | AJ11: 150000 | AK11: 0 | AL11: =SUM(Y11,Z11,AE11,AF11,AG11,AH11,AI11,AJ11) -> 1264000 | AM11: =X11+AL11 -> 2364000 | AN11: =AM11*AO11 -> 0 | AP11: =N11 -> 0 | AQ11: =AO11*AP11 -> 0 | AR11: 0 | AS11: 0 | AT11: A | AU11: =SUM(AN11,AQ11,AR11,AS11) -> 0 | AV11: =B11 -> SITI FARIDAH,S.Pd,Paud.,Gr | AW11: =AM11-AU11 -> 2364000
A12: 2 | B12: ='Data Base TK Malili'!B9 -> IDAYATI,S.Pd.Gr | C12: ='Data Base TK Malili'!J9 -> Bendahara/Wali Kelas | D12: =F12+I12 -> 24 | E12: 24 | F12: =E12-G12-I12 -> 24 | G12: 0 | H12: =E12-G12-I12-J12 -> 24 | I12: 0 | J12: 0 | K12: =E12-G12-L12-M12 -> 24 | L12: 0 | M12: 0 | N12: 0 | P12: ='Data Base TK Malili'!R9 -> S1 | Q12: ='Data Base TK Malili'!F9 -> 5 Tahun 0 Bulan 9 Hari | R12: 5 | S12: ='Data Base TK Malili'!G9 -> PT | T12: 1000000 | V12: ='Data Base TK Malili'!X9 -> 1 | W12: =V12*20000 -> 20000 | X12: =T12+U12+W12 -> 1020000 | AA12: 100000 | AE12: =SUM(AA12:AD12) -> 100000 | AF12: =F12*7000 -> 168000 | AG12: =H12*5000 -> 120000 | AH12: =K12*5000 -> 120000 | AI12: =O12*5000 -> 0 | AJ12: 150000 | AK12: 0 | AL12: =SUM(Y12,Z12,AE12,AF12,AG12,AH12,AI12,AJ12) -> 658000 | AM12: =X12+AL12 -> 1678000 | AN12: =AM12*AO12 -> 0 | AP12: =N12 -> 0 | AQ12: =AO12*AP12 -> 0 | AR12: 0 | AS12: 0 | AT12: A | AU12: =SUM(AN12,AQ12,AR12,AS12) -> 0 | AV12: =B12 -> IDAYATI,S.Pd.Gr | AW12: =AM12-AU12 -> 1678000
A13: 3 | B13: ='Data Base TK Malili'!B10 -> NURHIDAYANTY,SE | C13: ='Data Base TK Malili'!J10 -> Wali Kelas | D13: =F13+I13 -> 24 | E13: 24 | F13: =E13-G13-I13 -> 24 | G13: 0 | H13: =E13-G13-I13-J13 -> 24 | I13: 0 | J13: 0 | K13: =E13-G13-L13-M13 -> 24 | L13: 0 | M13: 0 | N13: 0 | P13: ='Data Base TK Malili'!R10 -> S1 | Q13: ='Data Base TK Malili'!F10 -> 4 Tahun 0 Bulan 30 Hari | R13: 4 | S13: ='Data Base TK Malili'!G10 -> PT | T13: 950000 | V13: ='Data Base TK Malili'!X10 -> 0 | W13: =V13*20000 -> 0 | X13: =T13+U13+W13 -> 950000 | AA13: 100000 | AE13: =SUM(AA13:AD13) -> 100000 | AF13: =F13*7000 -> 168000 | AG13: =H13*5000 -> 120000 | AH13: =K13*5000 -> 120000 | AI13: =O13*5000 -> 0 | AJ13: 150000 | AK13: 0 | AL13: =SUM(Y13,Z13,AE13,AF13,AG13,AH13,AI13,AJ13) -> 658000 | AM13: =X13+AL13 -> 1608000 | AN13: =AM13*AO13 -> 0 | AP13: =N13 -> 0 | AQ13: =AO13*AP13 -> 0 | AR13: 0 | AS13: 0 | AT13: A | AU13: =SUM(AN13,AQ13,AR13,AS13) -> 0 | AV13: =B13 -> NURHIDAYANTY,SE | AW13: =AM13-AU13 -> 1608000
A14: 4 | B14: ='Data Base TK Malili'!B11 -> NURMIANTI | C14: ='Data Base TK Malili'!J11 -> Wali Kelas | D14: =F14+I14 -> 24 | E14: 24 | F14: =E14-G14-I14 -> 24 | G14: 0 | H14: =E14-G14-I14-J14 -> 24 | I14: 0 | J14: 0 | K14: =E14-G14-L14-M14 -> 24 | L14: 0 | M14: 0 | N14: 0 | P14: ='Data Base TK Malili'!R11 -> S1 | Q14: ='Data Base TK Malili'!F11 -> 2 Tahun 1 Bulan 0 Hari | R14: 2 | S14: ='Data Base TK Malili'!G11 -> PT | T14: 900000 | V14: ='Data Base TK Malili'!X11 -> 2 | W14: =V14*20000 -> 40000 | X14: =T14+U14+W14 -> 940000 | AA14: 100000 | AE14: =SUM(AA14:AD14) -> 100000 | AF14: =F14*7000 -> 168000 | AG14: =H14*5000 -> 120000 | AH14: =K14*5000 -> 120000 | AI14: =O14*5000 -> 0 | AJ14: 150000 | AK14: 0 | AL14: =SUM(Y14,Z14,AE14,AF14,AG14,AH14,AI14,AJ14) -> 658000 | AM14: =X14+AL14 -> 1598000 | AN14: =AM14*AO14 -> 0 | AP14: =N14 -> 0 | AQ14: =AO14*AP14 -> 0 | AR14: 0 | AS14: 0 | AT14: A | AU14: =SUM(AN14,AQ14,AR14,AS14) -> 0 | AV14: =B14 -> NURMIANTI | AW14: =AM14-AU14 -> 1598000
A15: 5 | B15: ='Data Base TK Malili'!B12 -> FITRIANI | C15: ='Data Base TK Malili'!J12 -> Wali Kelas | D15: =F15+I15 -> 24 | E15: 24 | F15: =E15-G15-I15 -> 24 | G15: 0 | H15: =E15-G15-I15-J15 -> 24 | I15: 0 | J15: 0 | K15: =E15-G15-L15-M15 -> 24 | L15: 0 | M15: 0 | N15: 0 | P15: ='Data Base TK Malili'!R12 -> SMA | Q15: ='Data Base TK Malili'!F12 -> 1 Tahun 1 Bulan 1 Hari | R15: 1 | S15: ='Data Base TK Malili'!G12 -> PK | T15: 300000 | V15: ='Data Base TK Malili'!X12 -> 1 | W15: =V15*20000 -> 20000 | X15: =T15+U15+W15 -> 320000 | AA15: 100000 | AE15: =SUM(AA15:AD15) -> 100000 | AF15: =F15*7000 -> 168000 | AG15: =H15*5000 -> 120000 | AH15: =K15*5000 -> 120000 | AI15: =O15*5000 -> 0 | AJ15: 150000 | AK15: 0 | AL15: =SUM(Y15,Z15,AE15,AF15,AG15,AH15,AI15,AJ15) -> 658000 | AM15: =X15+AL15 -> 978000 | AN15: =AM15*AO15 -> 0 | AP15: =N15 -> 0 | AQ15: =AO15*AP15 -> 0 | AR15: 0 | AS15: 0 | AT15: A | AU15: =SUM(AN15,AQ15,AR15,AS15) -> 0 | AV15: =B15 -> FITRIANI | AW15: =AM15-AU15 -> 978000
A16: 6 | B16: ='Data Base TK Malili'!B13 -> NURAINI PUSPITA,S.Pdi | C16: ='Data Base TK Malili'!J13 -> Wali Kelas | D16: =F16+I16 -> 24 | E16: 24 | F16: =E16-G16-I16 -> 24 | G16: 0 | H16: =E16-G16-I16-J16 -> 24 | I16: 0 | J16: 0 | K16: =E16-G16-L16-M16 -> 24 | L16: 0 | M16: 0 | N16: 0 | P16: ='Data Base TK Malili'!R13 -> S1 | Q16: ='Data Base TK Malili'!F13 -> 0 Tahun 10 Bulan 18 Hari | R16: 0 | S16: ='Data Base TK Malili'!G13 -> PK | T16: 500000 | V16: ='Data Base TK Malili'!X13 -> 0 | W16: =V16*20000 -> 0 | X16: =T16+U16+W16 -> 500000 | AA16: 100000 | AE16: =SUM(AA16:AD16) -> 100000 | AF16: =F16*7000 -> 168000 | AG16: =H16*5000 -> 120000 | AH16: =K16*5000 -> 120000 | AI16: =O16*5000 -> 0 | AJ16: 150000 | AK16: 0 | AL16: =SUM(Y16,Z16,AE16,AF16,AG16,AH16,AI16,AJ16) -> 658000 | AM16: =X16+AL16 -> 1158000 | AN16: =AM16*AO16 -> 0 | AP16: =N16 -> 0 | AQ16: =AO16*AP16 -> 0 | AR16: 0 | AS16: 0 | AT16: A | AU16: =SUM(AN16,AQ16,AR16,AS16) -> 0 | AV16: =B16 -> NURAINI PUSPITA,S.Pdi | AW16: =AM16-AU16 -> 1158000
A17: 7 | B17: ='Data Base TK Malili'!B14 -> 0 | C17: ='Data Base TK Malili'!J14 -> 0 | N17: 0 | P17: ='Data Base TK Malili'!R14 -> 0 | Q17: ='Data Base TK Malili'!F14 -> 0 | AE17: =SUM(AA17:AD17) -> 0 | AF17: =F17*7000 -> 0 | AG17: =H17*5000 -> 0 | AH17: =K17*5000 -> 0 | AI17: =O17*5000 -> 0 | AK17: 0 | AL17: =SUM(Y17,Z17,AE17,AF17,AG17,AH17,AI17,AJ17) -> 0 | AM17: =X17+AL17 -> 0 | AN17: =AM17*AO17 -> 0 | AP17: =N17 -> 0 | AQ17: =AO17*AP17 -> 0 | AR17: 0 | AS17: 0 | AT17: A | AU17: =SUM(AN17,AQ17,AR17,AS17) -> 0 | AV17: =B17 -> 0 | AW17: =AM17-AU17 -> 0
A18: 8 | B18: ='Data Base TK Malili'!B15 -> 0 | C18: ='Data Base TK Malili'!J15 -> 0 | N18: 0 | P18: ='Data Base TK Malili'!R15 -> 0 | Q18: ='Data Base TK Malili'!F15 -> 0 | AE18: =SUM(AA18:AD18) -> 0 | AF18: =F18*7000 -> 0 | AG18: =H18*5000 -> 0 | AH18: =K18*5000 -> 0 | AI18: =O18*5000 -> 0 | AK18: 0 | AL18: =SUM(Y18,Z18,AE18,AF18,AG18,AH18,AI18,AJ18) -> 0 | AM18: =X18+AL18 -> 0 | AN18: =AM18*AO18 -> 0 | AP18: =N18 -> 0 | AQ18: =AO18*AP18 -> 0 | AR18: 0 | AS18: 0 | AT18: A | AU18: =SUM(AN18,AQ18,AR18,AS18) -> 0 | AV18: =B18 -> 0 | AW18: =AM18-AU18 -> 0
C19: ='Data Base TK Malili'!J16 -> 0 | AW19: =SUM(AW11:AW18) -> 9384000
B20: ='Data Base Guru SD'!B44 -> 0 | Q20: ='Data Base Guru SD'!F44 -> 0

Sheet Slip Gaji TK
D3: RINCIAN PENDAPATAN | H3: 1
D4: A. Pendapatan Wajib
D5: 1. Gaji Pokok | E5: =IF(LEN(VLOOKUP(H3,'TK Malili'!$A$11:$AX$49,20,FALSE))=0," ",VLOOKUP(H3,'TK Malili'!$A$11:$AX$49,20,FALSE)) -> 1100000
D6: 2. Istri | E6: =IF(LEN(VLOOKUP(H3,'TK Malili'!$A$11:$AW$49,21,FALSE))=0," ",VLOOKUP(H3,'TK Malili'!$A$11:$AW$49,21,FALSE))
A7: SLIP GAJI | D7: 3. Anak | E7: =IF(LEN(VLOOKUP(H3,'TK Malili'!$A$11:$AW$49,23,FALSE))=0,"0",VLOOKUP(H3,'TK Malili'!$A$11:$AW$49,23,FALSE)) -> 0
A8: No | B8: =IF(LEN(VLOOKUP(H3,'TK Malili'!$A$11:$AX$49,1,FALSE))=0," ",VLOOKUP(H3,'TK Malili'!$A$11:$AX$49,1,FALSE)) -> 1 | D8: Total A | E8: =SUM(E5:E7) -> 1100000
A9: Nama | B9: =IF(LEN(VLOOKUP(H3,'TK Malili'!$A$11:$AX$49,2,FALSE))=0," ",VLOOKUP(H3,'TK Malili'!$A$11:$AX$49,2,FALSE)) -> SITI FARIDAH,S.Pd,Paud.,Gr | D9: B. Tunjangan Pendapatan
D10: 1. Stuktural | E10: =IF(LEN(VLOOKUP(H3,'TK Malili'!$A$11:$AW$49,25,FALSE))=0,"0",VLOOKUP(H3,'TK Malili'!$A$11:$AW$49,25,FALSE)) -> 500000
A11: ='TK Malili'!B3 -> Periode 26 Juni 2026 s/d 25 Juli 2026 | D11: 2. Pengabdian | E11: =IF(LEN(VLOOKUP(H3,'TK Malili'!$A$11:$AW$49,26,FALSE))=0,"0",VLOOKUP(H3,'TK Malili'!$A$11:$AW$49,26,FALSE)) -> 150000
A12: ='TK Malili'!B4 -> TKIT INSAN RABBANI | D12: 3. Fungsional | E12: =IF(LEN(VLOOKUP(H3,'TK Malili'!$A$11:$AW$49,31,FALSE))=0,"0",VLOOKUP(H3,'TK Malili'!$A$11:$AW$49,31,FALSE)) -> 100000
A13: Hari Efektif Kerja | C13: =IF(LEN(VLOOKUP(H3,'TK Malili'!$A$11:$AX$49,5,FALSE))=0," ",VLOOKUP(H3,'TK Malili'!$A$11:$AX$49,5,FALSE)) -> 24 | D13: 4. Pendapatan Hari Efektif :
A14: Kehadiran | C14: =IF(LEN(VLOOKUP(H3,'TK Malili'!$A$11:$AX$49,6,FALSE))=0," ",VLOOKUP(H3,'TK Malili'!$A$11:$AX$49,6,FALSE)) -> 22 | D14: a. Absensi Kedatangan | E14: =IF(LEN(VLOOKUP(H3,'TK Malili'!$A$11:$AW$49,33,FALSE))=0,"0",VLOOKUP(H3,'TK Malili'!$A$11:$AW$49,33,FALSE)) -> 105000
A15: Tidak Hadir | C15: =IF(LEN(VLOOKUP(H3,'TK Malili'!$A$11:$AX$49,7,FALSE))=0," ",VLOOKUP(H3,'TK Malili'!$A$11:$AX$49,7,FALSE)) -> 1 | D15: b. Absensi Kepulangan | E15: =IF(LEN(VLOOKUP(H3,'TK Malili'!$A$11:$AW$49,34,FALSE))=0,"0",VLOOKUP(H3,'TK Malili'!$A$11:$AW$49,34,FALSE)) -> 105000
A16: Hadir Terlambat | C16: =IF(LEN(VLOOKUP(H3,'TK Malili'!$A$11:$AX$49,9,FALSE))=0," ",VLOOKUP(H3,'TK Malili'!$A$11:$AX$49,9,FALSE)) -> 1 | D16: c. Transportasi | E16: =IF(LEN(VLOOKUP(H3,'TK Malili'!$A$11:$AW$49,32,FALSE))=0,"0",VLOOKUP(H3,'TK Malili'!$A$11:$AW$49,32,FALSE)) -> 154000
A17: Tidak Absen Pulang | C17: =IF(LEN(VLOOKUP(H3,'TK Malili'!$A$11:$AX$49,13,FALSE))=0," ",VLOOKUP(H3,'TK Malili'!$A$11:$AX$49,13,FALSE)) -> 1 | D17: 5. KJM | E17: =IF(LEN(VLOOKUP(H3,'TK Malili'!$A$11:$AW$49,35,FALSE))=0,"0",VLOOKUP(H3,'TK Malili'!$A$11:$AW$49,35,FALSE)) -> 0
A18: Tidak Absen Masuk | C18: =IF(LEN(VLOOKUP(H3,'TK Malili'!$A$11:$AX$49,10,FALSE))=0," ",VLOOKUP(H3,'TK Malili'!$A$11:$AX$49,10,FALSE)) -> 1 | D18: 7. Penilaian Kinerja | E18: =IF(LEN(VLOOKUP(H3,'TK Malili'!$A$11:$AW$49,36,FALSE))=0,"0",VLOOKUP(H3,'TK Malili'!$A$11:$AW$49,36,FALSE)) -> 150000
A19: Cepat Pulang | C19: =IF(LEN(VLOOKUP(H3,'TK Malili'!$A$11:$AX$49,12,FALSE))=0," ",VLOOKUP(H3,'TK Malili'!$A$11:$AX$49,12,FALSE)) -> 1 | D19: 8. Tunjangan Apresiasi | E19: =IF(LEN(VLOOKUP(H3,'TK Malili'!$A$11:$AW$49,37,FALSE))=0,"0",VLOOKUP(H3,'TK Malili'!$A$11:$AW$49,37,FALSE)) -> 0
A20: Predikat Kinerja | C20: =IF(LEN(VLOOKUP(H3,'TK Malili'!$A$11:$AX$49,46,FALSE))=0,"0",VLOOKUP(H3,'TK Malili'!$A$11:$AX$49,46,FALSE)) -> A
A21: " Hai orang-orang beriman, makanlah diantara rezeki yang baik-baik kami berikan kepadamu dan bersyukurlah kepada Allah, jika benar-benar kepada Nya kamu menyembah
D24: Total B | E24: =SUM(E10:E23) -> 1264000
A25: Dicetak : | B25: ='TK Malili'!B4 -> TKIT INSAN RABBANI | D25: C. Pemotongan
D26: 1. Ta`awun | E26: =IF(LEN(VLOOKUP(H3,'TK Malili'!$A$11:$AW$49,44,FALSE))=0,"0",VLOOKUP(H3,'TK Malili'!$A$11:$AW$49,44,FALSE)) -> 0
D27: 2. SIM-T | E27: =IF(LEN(VLOOKUP(H3,'TK Malili'!$A$11:$AW$49,43,FALSE))=0,"0",VLOOKUP(H3,'TK Malili'!$A$11:$AW$49,43,FALSE)) -> 0
D28: 3. Pinjaman | E28: =IF(LEN(VLOOKUP(H3,'TK Malili'!$A$11:$AW$49,45,FALSE))=0,"0",VLOOKUP(H3,'TK Malili'!$A$11:$AW$49,45,FALSE)) -> 0
D29: 4. Pemotongan Luar Cuti | E29: =IF(LEN(VLOOKUP(H3,'TK Malili'!$A$11:$AW$49,40,FALSE))=0,"0",VLOOKUP(H3,'TK Malili'!$A$11:$AW$49,40,FALSE)) -> 0
D30: Total C | E30: =SUM(E26:E29) -> 0
B31: Bendahar Yayasan | D31: Rekapitulasi Akhir
D32: Total A,B | E32: =SUM(E8,E24) -> 2364000
D33: Total C | E33: =E30 -> 0
D34: Total Pendapatan | E34: =E32-E33 -> 2364000

Sheet REKAP KAFALAH TK
A1: REKAPAN KAFALAH BULAN
A2: ='TK Malili'!B3 -> Periode 26 Juni 2026 s/d 25 Juli 2026
A3: ='TK Malili'!B4 -> TKIT INSAN RABBANI
A4: NO | B4: NAMA | C4: TOTAL PENDAPATAN WAJIB | D4: TOTAL PENDAPATAN INSENTIF | E4: POTONGAN | F4: TOTAL KAFALAH YANG DITERIMA
A5: 1 | B5: ='TK Malili'!B11 -> SITI FARIDAH,S.Pd,Paud.,Gr | C5: ='TK Malili'!X11 -> 1100000 | D5: ='TK Malili'!AL11 -> 1264000 | E5: ='TK Malili'!AU11 -> 0 | F5: ='TK Malili'!AW11 -> 2364000
A6: 2 | B6: ='TK Malili'!B12 -> IDAYATI,S.Pd.Gr | C6: ='TK Malili'!X12 -> 1020000 | D6: ='TK Malili'!AL12 -> 658000 | E6: ='TK Malili'!AU12 -> 0 | F6: ='TK Malili'!AW12 -> 1678000
A7: 3 | B7: ='TK Malili'!B13 -> NURHIDAYANTY,SE | C7: ='TK Malili'!X13 -> 950000 | D7: ='TK Malili'!AL13 -> 658000 | E7: ='TK Malili'!AU13 -> 0 | F7: ='TK Malili'!AW13 -> 1608000
A8: 4 | B8: ='TK Malili'!B14 -> NURMIANTI | C8: ='TK Malili'!X14 -> 940000 | D8: ='TK Malili'!AL14 -> 658000 | E8: ='TK Malili'!AU14 -> 0 | F8: ='TK Malili'!AW14 -> 1598000
A9: 5 | B9: ='TK Malili'!B15 -> FITRIANI | C9: ='TK Malili'!X15 -> 320000 | D9: ='TK Malili'!AL15 -> 658000 | E9: ='TK Malili'!AU15 -> 0 | F9: ='TK Malili'!AW15 -> 978000
A10: 6 | B10: ='TK Malili'!B16 -> NURAINI PUSPITA,S.Pdi | C10: ='TK Malili'!X16 -> 500000 | D10: ='TK Malili'!AL16 -> 658000 | E10: ='TK Malili'!AU16 -> 0 | F10: ='TK Malili'!AW16 -> 1158000
A11: 7 | B11: ='TK Malili'!B17 -> 0 | C11: ='TK Malili'!X17 -> 0 | D11: ='TK Malili'!AL17 -> 0 | E11: ='TK Malili'!AU17 -> 0 | F11: ='TK Malili'!AW17 -> 0
A12: Total | F12: =SUM(F5:F11) -> 9384000

Sheet Data Base Guru SD
A1: DATA BASE TENAGA PEGAWAI
A2: YAYASAN PENDIDIKAN
A3: UNIT SD IT
A4: TAHUN AJARAN 2024-2025
A6: No | B6: Nama | C6: Jenis Kelamin | D6: Tanggal Masuk | E6: Today | F6: Masa Kerja | G6: Status Kepegawaian (PP/PK/PT/INVAL) | H6: Golongan Kepegawaian | I6: NUPTK | J6: Jabatan | K6: NIY | L6: Tempat Kelahiran | M6: Tanggal Lahir | N6: Usia | O6: NIK | P6: Alamat KTP | Q6: Alamat Domisili Sekarang | R6: Ijazah Terakhir | S6: Ijazah Terakhir / Jurusan / PT | T6: Status Pernikahan | U6: Nama Suami/Istri | V6: No. BPJS Kesehatan | W6: NPWP | X6: Jumlah Anak | Y6: No. Telp | AA6: Nama Murrobbi/Murobbiyah | AB6: E-Mail | AC6: Pengalaman Kerja | AD6: Pelatihan Yang telah diikuti | AE6: Skill (kemampuan) yang dimiliki | AF6: Skill (kemampuan) yang ingin ditingkatkan | AG6: Kemampuan Berbahasa Asing | AH6: Keterangan
Y7: Pribadi | Z7: Keluarga
A8: 1 | B8: Hasmiati, S.Pd | C8: PR | D8: 41456 | E8: =TODAY() -> 46244 | F8: =DATEDIF(D8,E8,"y")&" "&"Tahun"&" "&DATEDIF(D8,E8,"ym")&" "&"Bulan"&" "&DATEDIF(D8,E8,"md")&" "&"Hari" -> 13 Tahun 1 Bulan 9 Hari | G8: PT | J8: Wali Kelas ( Mengaji ) | K8: 0109197905201302005 | L8: Macorawalie | M8: 29099 | N8: =DATEDIF(M8,E8,"y")&" "&"Tahun"&" "&DATEDIF(M8,E8,"ym")&" "&"Bulan"&" "&DATEDIF(M8,E8,"md")&" "&"Hari" -> 46 Tahun 11 Bulan 9 Hari | P8: 0 | R8: S1 | S8: S1/BHS.INDONESIA/STKIP MUHAMMADIYAH/2002 | T8: Menikah | U8: Sudarsono | V8: - | W8: 0 | X8: 7 | AB8: 0 | AC8: 0 | AD8: 0 | AE8: 0 | AF8: 0 | AG8: 0
A9: 2 | B9: Nur Fajriani Usman, S.S | C9: PR | D9: 42552 | E9: =TODAY() -> 46244 | F9: =DATEDIF(D9,E9,"y")&" "&"Tahun"&" "&DATEDIF(D9,E9,"ym")&" "&"Bulan"&" "&DATEDIF(D9,E9,"md")&" "&"Hari" -> 10 Tahun 1 Bulan 9 Hari | G9: PT | J9: Wali Kelas ( Mengaji ) | K9: 1212199307201602010 | L9: Same | M9: 34315 | N9: =DATEDIF(M9,E9,"y")&" "&"Tahun"&" "&DATEDIF(M9,E9,"ym")&" "&"Bulan"&" "&DATEDIF(M9,E9,"md")&" "&"Hari" -> 32 Tahun 7 Bulan 29 Hari | P9: 0 | R9: S1 | T9: Menikah | U9: Hawis | V9: 0 | W9: 0 | X9: 2 | Z9: 0 | AB9: 0 | AC9: 0 | AD9: 0 | AE9: 0 | AF9: 0 | AG9: 0
A10: 3 | B10: Ade Asmi Pratiwi, SE | C10: PR | D10: 42736 | E10: =TODAY() -> 46244 | F10: =DATEDIF(D10,E10,"y")&" "&"Tahun"&" "&DATEDIF(D10,E10,"ym")&" "&"Bulan"&" "&DATEDIF(D10,E10,"md")&" "&"Hari" -> 9 Tahun 7 Bulan 9 Hari | G10: PT | J10: Wali Kelas ( Mengaji ) | K10: 3010199301201702011 | L10: Balantang | M10: 31613 | N10: =DATEDIF(M10,E10,"y")&" "&"Tahun"&" "&DATEDIF(M10,E10,"ym")&" "&"Bulan"&" "&DATEDIF(M10,E10,"md")&" "&"Hari" -> 40 Tahun 0 Bulan 21 Hari | P10: 0 | R10: S1 | T10: Belum Menikah | V10: 0 | W10: 0 | X10: 0 | Z10: 0 | AB10: 0 | AC10: 0 | AD10: 0 | AE10: 0 | AF10: 0 | AG10: 0
A11: 4 | B11: Asrina, S.Pd | C11: PR | D11: 42917 | E11: =TODAY() -> 46244 | F11: =DATEDIF(D11,E11,"y")&" "&"Tahun"&" "&DATEDIF(D11,E11,"ym")&" "&"Bulan"&" "&DATEDIF(D11,E11,"md")&" "&"Hari" -> 9 Tahun 1 Bulan 9 Hari | G11: PT | J11: Wali Kelas ( Mengaji ) | K11: 2908198307201702015 | L11: Sungguminasa | M11: 30557 | N11: =DATEDIF(M11,E11,"y")&" "&"Tahun"&" "&DATEDIF(M11,E11,"ym")&" "&"Bulan"&" "&DATEDIF(M11,E11,"md")&" "&"Hari" -> 42 Tahun 11 Bulan 12 Hari | P11: 0 | R11: S1 | T11: Menikah | V11: 0 | W11: 0 | X11: 2 | Z11: 0 | AB11: 0 | AC11: 0 | AD11: 0 | AE11: 0 | AF11: 0 | AG11: 0
A12: 5 | B12: Andi Kastiar Latif, S.Pd | C12: PR | D12: 42917 | E12: =TODAY() -> 46244 | F12: =DATEDIF(D12,E12,"y")&" "&"Tahun"&" "&DATEDIF(D12,E12,"ym")&" "&"Bulan"&" "&DATEDIF(D12,E12,"md")&" "&"Hari" -> 9 Tahun 1 Bulan 9 Hari | G12: PT | J12: Wali Kelas ( Mengaji ) | K12: 2312199307201702013 | L12: Sabah | M12: 35279 | N12: =DATEDIF(M12,E12,"y")&" "&"Tahun"&" "&DATEDIF(M12,E12,"ym")&" "&"Bulan"&" "&DATEDIF(M12,E12,"md")&" "&"Hari" -> 30 Tahun 0 Bulan 8 Hari | P12: 0 | R12: S1 | T12: Menikah | V12: 0 | W12: 0 | X12: 2 | Z12: 0 | AB12: 0 | AC12: 0 | AD12: 0 | AE12: 0 | AF12: 0 | AG12: 0
A13: 6 | B13: Harmawati. B, S.Pd | C13: PR | D13: 42917 | E13: =TODAY() -> 46244 | F13: =DATEDIF(D13,E13,"y")&" "&"Tahun"&" "&DATEDIF(D13,E13,"ym")&" "&"Bulan"&" "&DATEDIF(D13,E13,"md")&" "&"Hari" -> 9 Tahun 1 Bulan 9 Hari | G13: PT | J13: Wali Kelas ( Mengaji ) | K13: 3012199407201702014 | L13: Malili | M13: 34698 | N13: =DATEDIF(M13,E13,"y")&" "&"Tahun"&" "&DATEDIF(M13,E13,"ym")&" "&"Bulan"&" "&DATEDIF(M13,E13,"md")&" "&"Hari" -> 31 Tahun 7 Bulan 11 Hari | P13: 0 | R13: SMA | T13: Menikah | V13: 0 | W13: 0 | X13: 3 | Z13: 0 | AB13: 0 | AC13: 0 | AD13: 0 | AE13: 0 | AF13: 0 | AG13: 0
A14: 7 | B14: Nurazizah,S.Pd | C14: PR | D14: 42736 | E14: =TODAY() -> 46244 | F14: =DATEDIF(D14,E14,"y")&" "&"Tahun"&" "&DATEDIF(D14,E14,"ym")&" "&"Bulan"&" "&DATEDIF(D14,E14,"md")&" "&"Hari" -> 9 Tahun 7 Bulan 9 Hari | G14: PT | J14: Mengaji | K14: 2907199001201702016 | L14: Makassar | M14: 33083 | N14: =DATEDIF(M14,E14,"y")&" "&"Tahun"&" "&DATEDIF(M14,E14,"ym")&" "&"Bulan"&" "&DATEDIF(M14,E14,"md")&" "&"Hari" -> 36 Tahun 0 Bulan 12 Hari | P14: 0 | R14: S1 | T14: Menikah | V14: 0 | W14: 0 | X14: 0 | Z14: 0 | AB14: 0 | AC14: 0 | AD14: 0 | AE14: 0 | AF14: 0 | AG14: 0
A15: 8 | B15: Sri Rahayu, S.Pd | C15: PR | D15: 43132 | E15: =TODAY() -> 46244 | F15: =DATEDIF(D15,E15,"y")&" "&"Tahun"&" "&DATEDIF(D15,E15,"ym")&" "&"Bulan"&" "&DATEDIF(D15,E15,"md")&" "&"Hari" -> 8 Tahun 6 Bulan 9 Hari | G15: PT | J15: Mapel (Mengaji ) | K15: 2110199502201802018 | L15: Barantang | M15: 31341 | N15: =DATEDIF(M15,E15,"y")&" "&"Tahun"&" "&DATEDIF(M15,E15,"ym")&" "&"Bulan"&" "&DATEDIF(M15,E15,"md")&" "&"Hari" -> 40 Tahun 9 Bulan 20 Hari | P15: 0 | R15: S1 | T15: Menikah | V15: 0 | W15: 0 | X15: 0 | Z15: 0 | AB15: 0 | AC15: 0 | AD15: 0 | AE15: 0 | AF15: 0 | AG15: 0
A16: 9 | B16: Susilawati, S.Pd | C16: PR | D16: 43160 | E16: =TODAY() -> 46244 | F16: =DATEDIF(D16,E16,"y")&" "&"Tahun"&" "&DATEDIF(D16,E16,"ym")&" "&"Bulan"&" "&DATEDIF(D16,E16,"md")&" "&"Hari" -> 8 Tahun 5 Bulan 9 Hari | G16: PT | J16: Mapel (Mengaji ) | K16: 0709199003201802020 | L16: Malaysia | M16: 33123 | N16: =DATEDIF(M16,E16,"y")&" "&"Tahun"&" "&DATEDIF(M16,E16,"ym")&" "&"Bulan"&" "&DATEDIF(M16,E16,"md")&" "&"Hari" -> 35 Tahun 11 Bulan 3 Hari | P16: 0 | R16: S1 | T16: Menikah | V16: 0 | W16: 0 | X16: 3 | Z16: 0 | AB16: 0 | AC16: 0 | AD16: 0 | AE16: 0 | AF16: 0 | AG16: 0
A17: 10 | B17: Rismawati, S.Pd | C17: PR | D17: 43282 | E17: =TODAY() -> 46244 | F17: =DATEDIF(D17,E17,"y")&" "&"Tahun"&" "&DATEDIF(D17,E17,"ym")&" "&"Bulan"&" "&DATEDIF(D17,E17,"md")&" "&"Hari" -> 8 Tahun 1 Bulan 9 Hari | G17: PT | J17: Wali Kelas ( Mengaji ) | K17: 2505199507201802022 | L17: Malili | M17: 34844 | N17: =DATEDIF(M17,E17,"y")&" "&"Tahun"&" "&DATEDIF(M17,E17,"ym")&" "&"Bulan"&" "&DATEDIF(M17,E17,"md")&" "&"Hari" -> 31 Tahun 2 Bulan 16 Hari | P17: 0 | R17: S1 | T17: Belum Menikah | V17: 0 | W17: 0 | X17: 0 | Z17: 0 | AB17: 0 | AC17: 0 | AD17: 0 | AE17: 0 | AF17: 0 | AG17: 0
A18: 11 | B18: Ertika, S.Pd | C18: PR | D18: 43101 | E18: =TODAY() -> 46244 | F18: =DATEDIF(D18,E18,"y")&" "&"Tahun"&" "&DATEDIF(D18,E18,"ym")&" "&"Bulan"&" "&DATEDIF(D18,E18,"md")&" "&"Hari" -> 8 Tahun 7 Bulan 9 Hari | G18: PT | J18: Wali Kelas ( Mengaji ) | K18: 2703199607202502064 | L18: Tondojolo | M18: 35152 | N18: =DATEDIF(M18,E18,"y")&" "&"Tahun"&" "&DATEDIF(M18,E18,"ym")&" "&"Bulan"&" "&DATEDIF(M18,E18,"md")&" "&"Hari" -> 30 Tahun 4 Bulan 13 Hari | P18: 0 | R18: S1 | T18: Menikah | V18: 0 | W18: 0 | X18: 2 | Z18: 0 | AB18: 0 | AC18: 0 | AD18: 0 | AE18: 0 | AF18: 0 | AG18: 0
A19: 12 | B19: Kurniati, A.MA, Pd. OR | C19: PR | D19: 43374 | E19: =TODAY() -> 46244 | F19: =DATEDIF(D19,E19,"y")&" "&"Tahun"&" "&DATEDIF(D19,E19,"ym")&" "&"Bulan"&" "&DATEDIF(D19,E19,"md")&" "&"Hari" -> 7 Tahun 10 Bulan 9 Hari | G19: PT | J19: Mapel | K19: 0512198010201802024 | L19: Sorowako | M19: 29560 | N19: =DATEDIF(M19,E19,"y")&" "&"Tahun"&" "&DATEDIF(M19,E19,"ym")&" "&"Bulan"&" "&DATEDIF(M19,E19,"md")&" "&"Hari" -> 45 Tahun 8 Bulan 5 Hari | P19: 0 | R19: S1 | T19: Belum Menikah | V19: 0 | W19: 0 | X19: 0 | Z19: 0 | AB19: 0 | AC19: 0 | AD19: 0 | AE19: 0 | AF19: 0 | AG19: 0
A20: 13 | B20: Uppi Erniati H, S.Pd | C20: PR | D20: 43466 | E20: =TODAY() -> 46244 | F20: =DATEDIF(D20,E20,"y")&" "&"Tahun"&" "&DATEDIF(D20,E20,"ym")&" "&"Bulan"&" "&DATEDIF(D20,E20,"md")&" "&"Hari" -> 7 Tahun 7 Bulan 9 Hari | G20: PT | J20: Wali Kelas | K20: 1410198901201902026 | L20: Cerekang | M20: 32795 | N20: =DATEDIF(M20,E20,"y")&" "&"Tahun"&" "&DATEDIF(M20,E20,"ym")&" "&"Bulan"&" "&DATEDIF(M20,E20,"md")&" "&"Hari" -> 36 Tahun 9 Bulan 27 Hari | P20: 0 | R20: S1 | T20: Menikah | V20: 0 | W20: 0 | X20: 3 | Z20: 0 | AA20: 0 | AB20: 0 | AC20: 0 | AD20: 0 | AE20: 0 | AF20: 0 | AG20: 0
A21: 14 | B21: Dian Ekaviyanti Rusydi,SP | C21: PR | D21: 43647 | E21: =TODAY() -> 46244 | F21: =DATEDIF(D21,E21,"y")&" "&"Tahun"&" "&DATEDIF(D21,E21,"ym")&" "&"Bulan"&" "&DATEDIF(D21,E21,"md")&" "&"Hari" -> 7 Tahun 1 Bulan 9 Hari | G21: PT | J21: Wali Kelas ( Mengaji ) | K21: 0407198501201902027 | L21: Selayar | M21: 31232 | N21: =DATEDIF(M21,E21,"y")&" "&"Tahun"&" "&DATEDIF(M21,E21,"ym")&" "&"Bulan"&" "&DATEDIF(M21,E21,"md")&" "&"Hari" -> 41 Tahun 1 Bulan 6 Hari | P21: 0 | R21: S1 | T21: Menikah | V21: 0 | W21: 0 | X21: 4 | Z21: 0 | AA21: 0 | AB21: 0 | AC21: 0 | AD21: 0 | AE21: 0 | AF21: 0 | AG21: 0
A22: 15 | B22: Hasriani, S.Pd | C22: PR | D22: 43678 | E22: =TODAY() -> 46244 | F22: =DATEDIF(D22,E22,"y")&" "&"Tahun"&" "&DATEDIF(D22,E22,"ym")&" "&"Bulan"&" "&DATEDIF(D22,E22,"md")&" "&"Hari" -> 7 Tahun 0 Bulan 9 Hari | G22: PT | J22: Wali Kelas (Mengaji) | K22: 2303199508201902029 | L22: Kadong-kadong | M22: 34781 | N22: =DATEDIF(M22,E22,"y")&" "&"Tahun"&" "&DATEDIF(M22,E22,"ym")&" "&"Bulan"&" "&DATEDIF(M22,E22,"md")&" "&"Hari" -> 31 Tahun 4 Bulan 18 Hari | P22: 0 | R22: S1 | T22: Belum Menikah | V22: 0 | W22: 0 | X22: 0 | Z22: 0 | AA22: Darmawati | AB22: 0 | AC22: 0 | AD22: 0 | AE22: 0 | AF22: 0 | AG22: 0
A23: 16 | B23: Hildawati Dulla, S.Pd | C23: PR | D23: 43647 | E23: =TODAY() -> 46244 | F23: =DATEDIF(D23,E23,"y")&" "&"Tahun"&" "&DATEDIF(D23,E23,"ym")&" "&"Bulan"&" "&DATEDIF(D23,E23,"md")&" "&"Hari" -> 7 Tahun 1 Bulan 9 Hari | G23: PT | J23: Wali Kelas (Mengaji) | K23: 1612199501201902028 | L23: Kawata | M23: 35049 | N23: =DATEDIF(M23,E23,"y")&" "&"Tahun"&" "&DATEDIF(M23,E23,"ym")&" "&"Bulan"&" "&DATEDIF(M23,E23,"md")&" "&"Hari" -> 30 Tahun 7 Bulan 25 Hari | P23: 0 | R23: S1 | T23: Belum Menikah | V23: 0 | W23: 0 | X23: 0 | Z23: 085 237 314 250 | AA23: Akbar Ali, S. Pd.I | AB23: 0 | AC23: 0 | AD23: 0 | AE23: 0 | AF23: 0 | AG23: 0
A24: 17 | B24: Iin, S.Pd | C24: PR | D24: 43678 | E24: =TODAY() -> 46244 | F24: =DATEDIF(D24,E24,"y")&" "&"Tahun"&" "&DATEDIF(D24,E24,"ym")&" "&"Bulan"&" "&DATEDIF(D24,E24,"md")&" "&"Hari" -> 7 Tahun 0 Bulan 9 Hari | G24: PT | J24: Wali Kelas | K24: 2701199408201902031 | L24: Dadeko | M24: 34361 | N24: =DATEDIF(M24,E24,"y")&" "&"Tahun"&" "&DATEDIF(M24,E24,"ym")&" "&"Bulan"&" "&DATEDIF(M24,E24,"md")&" "&"Hari" -> 32 Tahun 6 Bulan 14 Hari | P24: 0 | R24: S1 | T24: Belum Menikah | V24: 0 | W24: 0 | X24: 2 | Z24: 0 | AA24: 0 | AB24: 0 | AC24: 0 | AD24: 0 | AE24: 0 | AF24: 0 | AG24: 0
A25: 18 | B25: Gisjawinta Ardo Maretza N | C25: PR | D25: 43647 | E25: =TODAY() -> 46244 | F25: =DATEDIF(D25,E25,"y")&" "&"Tahun"&" "&DATEDIF(D25,E25,"ym")&" "&"Bulan"&" "&DATEDIF(D25,E25,"md")&" "&"Hari" -> 7 Tahun 1 Bulan 9 Hari | G25: PT | J25: Wali Kelas (Mengaji) | K25: 2203199901201902030 | L25: Jayapura | M25: 36241 | N25: =DATEDIF(M25,E25,"y")&" "&"Tahun"&" "&DATEDIF(M25,E25,"ym")&" "&"Bulan"&" "&DATEDIF(M25,E25,"md")&" "&"Hari" -> 27 Tahun 4 Bulan 19 Hari | P25: 0 | R25: SMA | T25: Belum Menikah | V25: 0 | W25: 0 | X25: 0 | Z25: 0 | AA25: 0 | AB25: 0 | AC25: 0 | AD25: 0 | AE25: 0 | AF25: 0 | AG25: 0
A26: 19 | B26: Ita Nurhasanah S.Pd | C26: PR | D26: 44013 | E26: =TODAY() -> 46244 | F26: =DATEDIF(D26,E26,"y")&" "&"Tahun"&" "&DATEDIF(D26,E26,"ym")&" "&"Bulan"&" "&DATEDIF(D26,E26,"md")&" "&"Hari" -> 6 Tahun 1 Bulan 9 Hari | G26: PT | J26: Mapel (Mengaji) | K26: 1206199407202002031 | L26: Tawakua | M26: 34862 | N26: =DATEDIF(M26,E26,"y")&" "&"Tahun"&" "&DATEDIF(M26,E26,"ym")&" "&"Bulan"&" "&DATEDIF(M26,E26,"md")&" "&"Hari" -> 31 Tahun 1 Bulan 29 Hari | P26: 0 | R26: S1 | T26: Belum Menikah | V26: 0 | W26: 0 | X26: 0 | Z26: 0 | AA26: 0 | AB26: 0 | AC26: 0 | AD26: 0 | AE26: 0 | AF26: 0 | AG26: 0
A27: 20 | B27: Nurhaeni, S.Pd., M.Pd | C27: PR | D27: 45839 | E27: =TODAY() -> 46244 | F27: =DATEDIF(D27,E27,"y")&" "&"Tahun"&" "&DATEDIF(D27,E27,"ym")&" "&"Bulan"&" "&DATEDIF(D27,E27,"md")&" "&"Hari" -> 1 Tahun 1 Bulan 9 Hari | G27: PK | J27: Wali Kelas (Mengaji) | K27: 1509199606202502065 | L27: Bone | M27: 35323 | N27: =DATEDIF(M27,E27,"y")&" "&"Tahun"&" "&DATEDIF(M27,E27,"ym")&" "&"Bulan"&" "&DATEDIF(M27,E27,"md")&" "&"Hari" -> 29 Tahun 10 Bulan 26 Hari | P27: 0 | R27: S1 | T27: Belum Menikah | V27: 0 | W27: 0 | X27: 0 | Z27: 0 | AA27: Izzuddin, S. Pd.I | AB27: 0 | AC27: 0 | AD27: 0 | AE27: 0 | AF27: 0 | AG27: 0
A28: 21 | B28: Hidayatun Nisa S.Pd | C28: PR | D28: 44743 | E28: =TODAY() -> 46244 | F28: =DATEDIF(D28,E28,"y")&" "&"Tahun"&" "&DATEDIF(D28,E28,"ym")&" "&"Bulan"&" "&DATEDIF(D28,E28,"md")&" "&"Hari" -> 4 Tahun 1 Bulan 9 Hari | G28: PT | J28: Mapel(Mengaji) | K28: 0505200007202202050 | L28: Komba | M28: 36651 | N28: =DATEDIF(M28,E28,"y")&" "&"Tahun"&" "&DATEDIF(M28,E28,"ym")&" "&"Bulan"&" "&DATEDIF(M28,E28,"md")&" "&"Hari" -> 26 Tahun 3 Bulan 5 Hari | P28: 0 | R28: S1 | T28: Belum Menikah | V28: 0 | W28: 0 | X28: 0 | Z28: 0 | AA28: 0 | AB28: 0 | AC28: 0 | AD28: 0 | AE28: 0 | AF28: 0 | AG28: 0
A29: 22 | B29: Hizratul Laily S.H | C29: PR | D29: 44378 | E29: =TODAY() -> 46244 | F29: =DATEDIF(D29,E29,"y")&" "&"Tahun"&" "&DATEDIF(D29,E29,"ym")&" "&"Bulan"&" "&DATEDIF(D29,E29,"md")&" "&"Hari" -> 5 Tahun 1 Bulan 9 Hari | G29: PT | J29: Mapel(Mengaji) | K29: 0709199707202102038 | L29: Sumber Ase | M29: 35710 | N29: =DATEDIF(M29,E29,"y")&" "&"Tahun"&" "&DATEDIF(M29,E29,"ym")&" "&"Bulan"&" "&DATEDIF(M29,E29,"md")&" "&"Hari" -> 28 Tahun 10 Bulan 3 Hari | P29: 0 | R29: S1 | T29: Belum Menikah | V29: 0 | W29: 0 | X29: 0 | Z29: 0 | AA29: 0 | AB29: 0 | AC29: 0 | AD29: 0 | AE29: 0 | AF29: 0 | AG29: 0
A30: 23 | B30: Dwi Oktaviana S.Pd | C30: PR | D30: 44378 | E30: =TODAY() -> 46244 | F30: =DATEDIF(D30,E30,"y")&" "&"Tahun"&" "&DATEDIF(D30,E30,"ym")&" "&"Bulan"&" "&DATEDIF(D30,E30,"md")&" "&"Hari" -> 5 Tahun 1 Bulan 9 Hari | G30: PT | J30: Wali Kelas | K30: 2610199807202102040 | L30: Bone-bone | M30: 36094 | N30: =DATEDIF(M30,E30,"y")&" "&"Tahun"&" "&DATEDIF(M30,E30,"ym")&" "&"Bulan"&" "&DATEDIF(M30,E30,"md")&" "&"Hari" -> 27 Tahun 9 Bulan 15 Hari | P30: 0 | R30: S1 | T30: Belum Menikah | V30: 0 | W30: 0 | X30: 0 | Z30: 0 | AA30: Nurbayani | AB30: 0 | AC30: 0 | AD30: 0 | AE30: 0 | AF30: 0 | AG30: 0
A31: 24 | B31: Julianti S.Pd | C31: PR | D31: 44927 | E31: =TODAY() -> 46244 | F31: =DATEDIF(D31,E31,"y")&" "&"Tahun"&" "&DATEDIF(D31,E31,"ym")&" "&"Bulan"&" "&DATEDIF(D31,E31,"md")&" "&"Hari" -> 3 Tahun 7 Bulan 9 Hari | G31: PT | J31: Wali Kelas | K31: 1207200001202302053 | L31: Lakawali | M31: 36719 | N31: =DATEDIF(M31,E31,"y")&" "&"Tahun"&" "&DATEDIF(M31,E31,"ym")&" "&"Bulan"&" "&DATEDIF(M31,E31,"md")&" "&"Hari" -> 26 Tahun 0 Bulan 29 Hari | P31: 0 | R31: S1 | T31: Menikah | V31: 0 | W31: 0 | X31: 0 | Z31: 0 | AA31: Nurbayani | AB31: 0 | AC31: 0 | AD31: 0 | AE31: 0 | AF31: 0 | AG31: 0
A32: 25 | B32: Nadia Azzahrah | C32: PR | D32: 45474 | E32: =TODAY() -> 46244 | F32: =DATEDIF(D32,E32,"y")&" "&"Tahun"&" "&DATEDIF(D32,E32,"ym")&" "&"Bulan"&" "&DATEDIF(D32,E32,"md")&" "&"Hari" -> 2 Tahun 1 Bulan 9 Hari | G32: PK | J32: Guru Mapel (mengaji) | K32: 2703200607202402059 | L32: Wulasi | M32: 38803 | N32: =DATEDIF(M32,E32,"y")&" "&"Tahun"&" "&DATEDIF(M32,E32,"ym")&" "&"Bulan"&" "&DATEDIF(M32,E32,"md")&" "&"Hari" -> 20 Tahun 4 Bulan 14 Hari | P32: 0 | R32: SMA | T32: Belum Menikah | V32: 0 | W32: 0 | X32: 0 | Z32: 081 339 614 294 | AA32: Akbar Ali, S. Pd.I | AB32: 0 | AC32: 0 | AD32: 0 | AE32: 0 | AF32: 0 | AG32: 0
A33: 26 | B33: Nur Halisah Aminun S.Pd | C33: PR | D33: 44562 | E33: =TODAY() -> 46244 | F33: =DATEDIF(D33,E33,"y")&" "&"Tahun"&" "&DATEDIF(D33,E33,"ym")&" "&"Bulan"&" "&DATEDIF(D33,E33,"md")&" "&"Hari" -> 4 Tahun 7 Bulan 9 Hari | G33: PT | J33: Wali Kelas (Mengaji) | K33: 0604199901202202049 | L33: Malili | M33: 36256 | N33: =DATEDIF(M33,E33,"y")&" "&"Tahun"&" "&DATEDIF(M33,E33,"ym")&" "&"Bulan"&" "&DATEDIF(M33,E33,"md")&" "&"Hari" -> 27 Tahun 4 Bulan 4 Hari | O33: 0 | P33: 0 | R33: S1 | T33: Belum Menikah | V33: 0 | W33: 0 | X33: 0 | Z33: 0 | AA33: 0 | AB33: 0 | AC33: 0 | AD33: 0 | AE33: 0 | AF33: 0 | AG33: 0
A34: 27 | B34: Sri Mulyani S.Pd | C34: PR | D34: 44501 | E34: =TODAY() -> 46244 | F34: =DATEDIF(D34,E34,"y")&" "&"Tahun"&" "&DATEDIF(D34,E34,"ym")&" "&"Bulan"&" "&DATEDIF(D34,E34,"md")&" "&"Hari" -> 4 Tahun 9 Bulan 9 Hari | G34: PT | J34: Wali Kelas | K34: 1705199811202102046 | L34: Tator | M34: 35932 | N34: =DATEDIF(M34,E34,"y")&" "&"Tahun"&" "&DATEDIF(M34,E34,"ym")&" "&"Bulan"&" "&DATEDIF(M34,E34,"md")&" "&"Hari" -> 28 Tahun 2 Bulan 24 Hari | O34: 0 | P34: 0 | R34: S1 | T34: Belum Menikah | V34: 0 | W34: 0 | X34: 0 | Z34: 0 | AA34: 0 | AB34: 0 | AC34: 0 | AD34: 0 | AE34: 0 | AF34: 0 | AG34: 0
A35: 28 | B35: Saidatul Musayyadah S.Pd | C35: PR | D35: 44593 | E35: =TODAY() -> 46244 | F35: =DATEDIF(D35,E35,"y")&" "&"Tahun"&" "&DATEDIF(D35,E35,"ym")&" "&"Bulan"&" "&DATEDIF(D35,E35,"md")&" "&"Hari" -> 4 Tahun 6 Bulan 9 Hari | G35: PT | J35: Mapel (Mengaji) | K35: 0112199802202202048 | L35: Komba | M35: 36130 | N35: =DATEDIF(M35,E35,"y")&" "&"Tahun"&" "&DATEDIF(M35,E35,"ym")&" "&"Bulan"&" "&DATEDIF(M35,E35,"md")&" "&"Hari" -> 27 Tahun 8 Bulan 9 Hari | O35: 0 | P35: 0 | R35: S1 | T35: Belum Menikah | V35: 0 | W35: 0 | X35: 0 | Z35: 0 | AA35: 0 | AB35: 0 | AC35: 0 | AD35: 0 | AE35: 0 | AF35: 0 | AG35: 0
A36: 29 | B36: Reski Elvira Sari S.Pd | C36: PR | D36: 44805 | E36: =TODAY() -> 46244 | F36: =DATEDIF(D36,E36,"y")&" "&"Tahun"&" "&DATEDIF(D36,E36,"ym")&" "&"Bulan"&" "&DATEDIF(D36,E36,"md")&" "&"Hari" -> 3 Tahun 11 Bulan 9 Hari | G36: PT | J36: Wali kelas | K36: 0707199909202202052 | L36: Sorowako | M36: 36348 | N36: =DATEDIF(M36,E36,"y")&" "&"Tahun"&" "&DATEDIF(M36,E36,"ym")&" "&"Bulan"&" "&DATEDIF(M36,E36,"md")&" "&"Hari" -> 27 Tahun 1 Bulan 3 Hari | O36: 0 | P36: 0 | R36: S1 | T36: Belum Menikah | V36: 0 | W36: 0 | X36: 0 | Z36: 0 | AA36: 0 | AB36: 0 | AC36: 0 | AD36: 0 | AE36: 0 | AF36: 0 | AG36: 0
A37: 30 | B37: Andini Putri Patrisia | C37: PR | D37: 46054 | E37: =TODAY() -> 46244 | F37: =DATEDIF(D37,E37,"y")&" "&"Tahun"&" "&DATEDIF(D37,E37,"ym")&" "&"Bulan"&" "&DATEDIF(D37,E37,"md")&" "&"Hari" -> 0 Tahun 6 Bulan 9 Hari | G37: PK | J37: TU | M37: 0 | N37: =DATEDIF(M37,E37,"y")&" "&"Tahun"&" "&DATEDIF(M37,E37,"ym")&" "&"Bulan"&" "&DATEDIF(M37,E37,"md")&" "&"Hari" -> 126 Tahun 7 Bulan 10 Hari | O37: 0 | P37: 0 | R37: SMA | T37: Menikah | V37: 0 | W37: 0 | X37: 0 | Z37: 0 | AA37: 0 | AB37: 0 | AC37: 0 | AD37: 0 | AE37: 0 | AF37: 0 | AG37: 0
A38: 31 | B38: Maya Puspita Djasnah S.Pd | C38: PR | D38: 44805 | E38: =TODAY() -> 46244 | F38: =DATEDIF(D38,E38,"y")&" "&"Tahun"&" "&DATEDIF(D38,E38,"ym")&" "&"Bulan"&" "&DATEDIF(D38,E38,"md")&" "&"Hari" -> 3 Tahun 11 Bulan 9 Hari | G38: PT | J38: Wali Kelas | K38: 1903198709202202051 | L38: Palopo | M38: 31855 | N38: =DATEDIF(M38,E38,"y")&" "&"Tahun"&" "&DATEDIF(M38,E38,"ym")&" "&"Bulan"&" "&DATEDIF(M38,E38,"md")&" "&"Hari" -> 39 Tahun 4 Bulan 22 Hari | R38: S1 | T38: Menikah | V38: 0 | W38: 0 | X38: 2 | Z38: 0 | AA38: 0 | AB38: 0 | AC38: Pernah Mengajar di SDN 221 Cempa | AD38: 0 | AE38: 0 | AF38: 0 | AG38: 0
A39: 32 | B39: Elvira Fitriana S.Pd | C39: PR | D39: 45231 | E39: =TODAY() -> 46244 | F39: =DATEDIF(D39,E39,"y")&" "&"Tahun"&" "&DATEDIF(D39,E39,"ym")&" "&"Bulan"&" "&DATEDIF(D39,E39,"md")&" "&"Hari" -> 2 Tahun 9 Bulan 9 Hari | G39: PK | J39: Wali Kelas | K39: 2105199909202302057 | L39: Nabire | M39: 36301 | N39: =DATEDIF(M39,E39,"y")&" "&"Tahun"&" "&DATEDIF(M39,E39,"ym")&" "&"Bulan"&" "&DATEDIF(M39,E39,"md")&" "&"Hari" -> 27 Tahun 2 Bulan 20 Hari | R39: S1 | T39: Menikah | V39: 0 | W39: 0 | X39: 2 | Z39: 0 | AA39: 0 | AB39: kasma3546@gmail.com | AC39: 0 | AD39: 0 | AE39: 0 | AF39: 0 | AG39: 0
A40: 33 | B40: Maya Prasetya S.E | C40: PR | D40: 45231 | E40: =TODAY() -> 46244 | F40: =DATEDIF(D40,E40,"y")&" "&"Tahun"&" "&DATEDIF(D40,E40,"ym")&" "&"Bulan"&" "&DATEDIF(D40,E40,"md")&" "&"Hari" -> 2 Tahun 9 Bulan 9 Hari | G40: PK | J40: Guru Mapel (mengaji) | K40: 1303199809202302056 | L40: Rampoang | M40: 35867 | N40: =DATEDIF(M40,E40,"y")&" "&"Tahun"&" "&DATEDIF(M40,E40,"ym")&" "&"Bulan"&" "&DATEDIF(M40,E40,"md")&" "&"Hari" -> 28 Tahun 4 Bulan 28 Hari | R40: S1 | T40: Menikah | V40: 0 | W40: 0 | X40: 2 | Z40: 0 | AA40: 0 | AB40: jumatizan@gmail.com | AC40: 0 | AD40: 0 | AE40: Trik Matematika cepat & Tepat | AF40: 0 | AG40: 0
A41: 34 | B41: Muthia | C41: PR | D41: 45474 | E41: =TODAY() -> 46244 | F41: =DATEDIF(D41,E41,"y")&" "&"Tahun"&" "&DATEDIF(D41,E41,"ym")&" "&"Bulan"&" "&DATEDIF(D41,E41,"md")&" "&"Hari" -> 2 Tahun 1 Bulan 9 Hari | G41: PK | J41: Guru Mapel (mengaji) | K41: 2401200607202402060 | L41: Macrowalie | M41: 38741 | N41: =DATEDIF(M41,E41,"y")&" "&"Tahun"&" "&DATEDIF(M41,E41,"ym")&" "&"Bulan"&" "&DATEDIF(M41,E41,"md")&" "&"Hari" -> 20 Tahun 6 Bulan 17 Hari | R41: SMA | T41: Belum Menikah | V41: 0 | W41: 0 | X41: 0 | Z41: 0 | AA41: 0 | AB41: ditasafitri419@gmail.com | AC41: 0 | AD41: 0 | AE41: 0 | AF41: 0 | AG41: 0
...

Sheet SDIT IR Malili 
A1: DRAFT STRUKTUR KAFALAH SDIT INSAN RABBANI
A2: TAHUN AJARAN 2026-2027
B3: Periode 26 Juni 2026 s/d 25 Juli 2026 | AJ3: 125000
B4: SDIT INSAN RABBANI | L4: Blok Merah kena Pelanggaran
B5: =TODAY() -> 46244 | L5: Blok Kuning Cuti
A6: A. PEGAWAI TETAP YAYASAN (BERHENTI/DIBERHENTIKAN)
A7: 1 | B7: 2 | C7: 3 | D7: 4 | E7: 5 | F7: 6 | G7: 7 | H7: 8 | I7: 9 | J7: 10 | K7: 11 | L7: 12 | M7: 13 | N7: 14 | O7: 15 | P7: 16 | Q7: 17 | R7: 18 | S7: 19 | T7: 20 | U7: 21 | V7: 22 | W7: 23 | X7: 24 | Y7: 25 | Z7: 26 | AA7: 27 | AB7: 28 | AC7: 29 | AD7: 30 | AE7: 31 | AF7: 32 | AG7: 33 | AH7: 34 | AI7: 35 | AJ7: 36 | AK7: 37 | AL7: 38 | AM7: 39 | AN7: 40 | AO7: 41 | AP7: 42 | AQ7: 43 | AR7: 44 | AS7: 45 | AT7: 46 | AU7: 47 | AV7: 48 | AW7: 49
A8: NO | B8: NAMA | C8: Jabatan | D8: Kehadiran Real | E8: HARI EFEKTIF | F8: KEHADIRAN | G8: TIDAK HADIR | H8: TEPAT WAKTU DATANG | I8: TERLAMBAT | J8: TIDAK ABSEN MASUK | K8: TIDAK CEPAT PULANG | L8: CEPAT PULANG | M8: TIDAK ABSEN PULANG | N8: DURASI SIM-T & Keterlambatan Mengajar | O8: KJM | P8: Starata | Q8: LAMA MENGABDI | R8: Jumlah Pengabdian | S8: Status Pegawai | T8: PENDAPATAN WAJIB | X8: TOTAL 1 | Y8: PENDAPATAN INSENTIF | AL8: TOTAL 2 | AM8: JUMLAH PENDAPATAN (TOTAL 1, 2,) | AN8: PEMOTONGAN | AU8: JUMLAH PEMOTONGAN | AV8: NAMA | AW8: TOTAL KAFALAH YANG DITERIMA
T9: KAFALAH POKOK | U9: TUNJ. KELUARGA | Y9: TUNJ. STRUKTURAL JABATAN | Z9: TUNJ. PENGABDIAN | AA9: TUNJ. FUNGSIONAL | AE9: TOTAL TUNJ. FUNGSIONAL | AF9: TUNJ. TRANSPORTASI | AG9: TUNJ. TEPAT WAKTU DATANG | AH9: TUNJ. TIDAK CEPAT PULANG | AI9: TUNJ. KJM | AJ9: TUNJ. PRESTASI KINERJA | AK9: TUNJ. APRESIASI | AN9: PEMOTONGAN LUAR TANGGUNGAN | AO9: Persen (%) Cuti Luar Tanggungan | AP9: DURASI SIM-T | AQ9: Jumlah Pemotongan SIM-T | AR9: Ta`awun | AS9: PINJAMAN | AT9: Predikat Kinerja
U10: ISTRI | V10: JML ANAK | W10: ANAK | AA10: 1 | AB10: 2 | AC10: 3 | AD10: 4
A11: 1 | B11: ='Data Base Guru SD'!B8 -> Hasmiati, S.Pd | C11: ='Data Base Guru SD'!J8 -> Wali Kelas ( Mengaji ) | D11: =F11+I11 -> 24 | E11: 24 | F11: =E11-G11-I11 -> 24 | G11: 0 | H11: =E11-G11-I11-J11 -> 24 | I11: 0 | J11: 0 | K11: =E11-G11-L11-M11 -> 24 | L11: 0 | M11: 0 | O11: 48 | P11: ='Data Base Guru SD'!R8 -> S1 | Q11: ='Data Base Guru SD'!F8 -> 13 Tahun 1 Bulan 9 Hari | R11: 13 | S11: ='Data Base Guru SD'!G8 -> PT | T11: 2100000 | V11: ='Data Base Guru SD'!X8 -> 7 | W11: =V11*20000 -> 140000 | X11: =T11+U11+W11 -> 2240000 | Y11: 400000 | Z11: 175000 | AA11: 100000 | AE11: =SUM(AA11:AD11) -> 100000 | AF11: =F11*10000 -> 240000 | AG11: =H11*5000 -> 120000 | AH11: =K11*5000 -> 120000 | AI11: =O11*5000 -> 240000 | AJ11: 150000 | AK11: 0 | AL11: =SUM(Y11,Z11,AE11,AF11,AG11,AH11,AI11,AJ11) -> 1545000 | AM11: =X11+AL11 -> 3785000 | AN11: =AM11*AO11 -> 0 | AP11: =N11 -> 0 | AQ11: =AO11*AP11 -> 0 | AR11: 0 | AS11: 0 | AT11: A | AU11: =SUM(AN11,AQ11,AR11,AS11) -> 0 | AV11: =B11 -> Hasmiati, S.Pd | AW11: =AM11-AU11 -> 3785000
A12: 2 | B12: ='Data Base Guru SD'!B9 -> Nur Fajriani Usman, S.S | C12: ='Data Base Guru SD'!J9 -> Wali Kelas ( Mengaji ) | D12: =F12+I12 -> 24 | E12: 24 | F12: =E12-G12-I12 -> 24 | G12: 0 | H12: =E12-G12-I12-J12 -> 24 | I12: 0 | J12: 0 | K12: =E12-G12-L12-M12 -> 24 | L12: 0 | M12: 0 | O12: 48 | P12: ='Data Base Guru SD'!R9 -> S1 | Q12: ='Data Base Guru SD'!F9 -> 10 Tahun 1 Bulan 9 Hari | R12: 10 | S12: ='Data Base Guru SD'!G9 -> PT | T12: 2000000 | V12: ='Data Base Guru SD'!X9 -> 2 | W12: =V12*20000 -> 40000 | X12: =T12+U12+W12 -> 2040000 | Z12: 150000 | AA12: 100000 | AE12: =SUM(AA12:AD12) -> 100000 | AF12: =F12*10000 -> 240000 | AG12: =H12*5000 -> 120000 | AH12: =K12*5000 -> 120000 | AI12: =O12*5000 -> 240000 | AJ12: 150000 | AK12: 0 | AL12: =SUM(Y12,Z12,AE12,AF12,AG12,AH12,AI12,AJ12) -> 1120000 | AM12: =X12+AL12 -> 3160000 | AN12: =AM12*AO12 -> 0 | AP12: =N12 -> 0 | AQ12: =AO12*AP12 -> 0 | AS12: 0 | AT12: A | AU12: =SUM(AN12,AQ12,AR12,AS12) -> 0 | AV12: =B12 -> Nur Fajriani Usman, S.S | AW12: =AM12-AU12 -> 3160000
A13: 3 | B13: ='Data Base Guru SD'!B10 -> Ade Asmi Pratiwi, SE | C13: ='Data Base Guru SD'!J10 -> Wali Kelas ( Mengaji ) | D13: =F13+I13 -> 24 | E13: 24 | F13: =E13-G13-I13 -> 24 | G13: 0 | H13: =E13-G13-I13-J13 -> 24 | I13: 0 | J13: 0 | K13: =E13-G13-L13-M13 -> 24 | L13: 0 | M13: 0 | O13: 48 | P13: ='Data Base Guru SD'!R10 -> S1 | Q13: ='Data Base Guru SD'!F10 -> 9 Tahun 7 Bulan 9 Hari | R13: 9 | S13: ='Data Base Guru SD'!G10 -> PT | T13: 2000000 | V13: ='Data Base Guru SD'!X10 -> 0 | W13: =V13*20000 -> 0 | X13: =T13+U13+W13 -> 2000000 | Z13: 150000 | AA13: 100000 | AE13: =SUM(AA13:AD13) -> 100000 | AF13: =F13*10000 -> 240000 | AG13: =H13*5000 -> 120000 | AH13: =K13*5000 -> 120000 | AI13: =O13*5000 -> 240000 | AJ13: 150000 | AK13: 0 | AL13: =SUM(Y13,Z13,AE13,AF13,AG13,AH13,AI13,AJ13) -> 1120000 | AM13: =X13+AL13 -> 3120000 | AN13: =AM13*AO13 -> 0 | AP13: =N13 -> 0 | AQ13: =AO13*AP13 -> 0 | AS13: 0 | AT13: A | AU13: =SUM(AN13,AQ13,AR13,AS13) -> 0 | AV13: =B13 -> Ade Asmi Pratiwi, SE | AW13: =AM13-AU13 -> 3120000
A14: 4 | B14: ='Data Base Guru SD'!B11 -> Asrina, S.Pd | C14: ='Data Base Guru SD'!J11 -> Wali Kelas ( Mengaji ) | D14: =F14+I14 -> 24 | E14: 24 | F14: =E14-G14-I14 -> 24 | G14: 0 | H14: =E14-G14-I14-J14 -> 24 | I14: 0 | J14: 0 | K14: =E14-G14-L14-M14 -> 24 | L14: 0 | M14: 0 | O14: 48 | P14: ='Data Base Guru SD'!R11 -> S1 | Q14: ='Data Base Guru SD'!F11 -> 9 Tahun 1 Bulan 9 Hari | R14: 9 | S14: ='Data Base Guru SD'!G11 -> PT | T14: 2000000 | V14: ='Data Base Guru SD'!X11 -> 2 | W14: =V14*20000 -> 40000 | X14: =T14+U14+W14 -> 2040000 | Z14: 150000 | AA14: 100000 | AE14: =SUM(AA14:AD14) -> 100000 | AF14: =F14*10000 -> 240000 | AG14: =H14*5000 -> 120000 | AH14: =K14*5000 -> 120000 | AI14: =O14*5000 -> 240000 | AJ14: 150000 | AK14: 0 | AL14: =SUM(Y14,Z14,AE14,AF14,AG14,AH14,AI14,AJ14) -> 1120000 | AM14: =X14+AL14 -> 3160000 | AN14: =AM14*AO14 -> 0 | AP14: =N14 -> 0 | AQ14: =AO14*AP14 -> 0 | AS14: 0 | AT14: A | AU14: =SUM(AN14,AQ14,AR14,AS14) -> 0 | AV14: =B14 -> Asrina, S.Pd | AW14: =AM14-AU14 -> 3160000
A15: 5 | B15: ='Data Base Guru SD'!B12 -> Andi Kastiar Latif, S.Pd | C15: ='Data Base Guru SD'!J12 -> Wali Kelas ( Mengaji ) | D15: =F15+I15 -> 24 | E15: 24 | F15: =E15-G15-I15 -> 24 | G15: 0 | H15: =E15-G15-I15-J15 -> 24 | I15: 0 | J15: 0 | K15: =E15-G15-L15-M15 -> 24 | L15: 0 | M15: 0 | O15: 0 | P15: ='Data Base Guru SD'!R12 -> S1 | Q15: ='Data Base Guru SD'!F12 -> 9 Tahun 1 Bulan 9 Hari | R15: 9 | S15: ='Data Base Guru SD'!G12 -> PT | T15: 2000000 | V15: ='Data Base Guru SD'!X12 -> 2 | W15: =V15*20000 -> 40000 | X15: =T15+U15+W15 -> 2040000 | Y15: 800000 | Z15: 150000 | AE15: =SUM(AA15:AD15) -> 0 | AF15: =F15*10000 -> 240000 | AG15: =H15*5000 -> 120000 | AH15: =K15*5000 -> 120000 | AI15: =O15*5000 -> 0 | AJ15: 150000 | AK15: 0 | AL15: =SUM(Y15,Z15,AE15,AF15,AG15,AH15,AI15,AJ15) -> 1580000 | AM15: =X15+AL15 -> 3620000 | AN15: =AM15*AO15 -> 0 | AP15: =N15 -> 0 | AQ15: =AO15*AP15 -> 0 | AS15: 0 | AT15: A | AU15: =SUM(AN15,AQ15,AR15,AS15) -> 0 | AV15: =B15 -> Andi Kastiar Latif, S.Pd | AW15: =AM15-AU15 -> 3620000
A16: 6 | B16: ='Data Base Guru SD'!B13 -> Harmawati. B, S.Pd | C16: ='Data Base Guru SD'!J13 -> Wali Kelas ( Mengaji ) | D16: =F16+I16 -> 24 | E16: 24 | F16: =E16-G16-I16 -> 24 | G16: 0 | H16: =E16-G16-I16-J16 -> 24 | I16: 0 | J16: 0 | K16: =E16-G16-L16-M16 -> 24 | L16: 0 | M16: 0 | O16: 48 | P16: ='Data Base Guru SD'!R13 -> SMA | Q16: ='Data Base Guru SD'!F13 -> 9 Tahun 1 Bulan 9 Hari | R16: 9 | S16: ='Data Base Guru SD'!G13 -> PT | T16: 1000000 | V16: ='Data Base Guru SD'!X13 -> 3 | W16: =V16*20000 -> 60000 | X16: =T16+U16+W16 -> 1060000 | Z16: 150000 | AA16: 100000 | AE16: =SUM(AA16:AD16) -> 100000 | AF16: =F16*10000 -> 240000 | AG16: =H16*5000 -> 120000 | AH16: =K16*5000 -> 120000 | AI16: =O16*5000 -> 240000 | AJ16: 150000 | AK16: 0 | AL16: =SUM(Y16,Z16,AE16,AF16,AG16,AH16,AI16,AJ16) -> 1120000 | AM16: =X16+AL16 -> 2180000 | AN16: =AM16*AO16 -> 0 | AP16: =N16 -> 0 | AQ16: =AO16*AP16 -> 0 | AS16: 0 | AT16: A | AU16: =SUM(AN16,AQ16,AR16,AS16) -> 0 | AV16: =B16 -> Harmawati. B, S.Pd | AW16: =AM16-AU16 -> 2180000
A17: 7 | B17: ='Data Base Guru SD'!B14 -> Nurazizah,S.Pd | C17: ='Data Base Guru SD'!J14 -> Mengaji | D17: =F17+I17 -> 24 | E17: 24 | F17: =E17-G17-I17 -> 24 | G17: 0 | H17: =E17-G17-I17-J17 -> 24 | I17: 0 | J17: 0 | K17: =E17-G17-L17-M17 -> 24 | L17: 0 | M17: 0 | O17: 40 | P17: ='Data Base Guru SD'!R14 -> S1 | Q17: ='Data Base Guru SD'!F14 -> 9 Tahun 7 Bulan 9 Hari | R17: 9 | S17: ='Data Base Guru SD'!G14 -> PT | T17: 2000000 | V17: ='Data Base Guru SD'!X14 -> 0 | W17: =V17*20000 -> 0 | X17: =T17+U17+W17 -> 2000000 | Z17: 150000 | AE17: =SUM(AA17:AD17) -> 0 | AF17: =F17*10000 -> 240000 | AG17: =H17*5000 -> 120000 | AH17: =K17*5000 -> 120000 | AI17: =O17*5000 -> 200000 | AJ17: 150000 | AK17: 0 | AL17: =SUM(Y17,Z17,AE17,AF17,AG17,AH17,AI17,AJ17) -> 980000 | AM17: =X17+AL17 -> 2980000 | AN17: =AM17*AO17 -> 0 | AP17: =N17 -> 0 | AQ17: =AO17*AP17 -> 0 | AS17: 0 | AT17: A | AU17: =SUM(AN17,AQ17,AR17,AS17) -> 0 | AV17: =B17 -> Nurazizah,S.Pd | AW17: =AM17-AU17 -> 2980000
A18: 8 | B18: ='Data Base Guru SD'!B15 -> Sri Rahayu, S.Pd | C18: ='Data Base Guru SD'!J15 -> Mapel (Mengaji ) | D18: =F18+I18 -> 24 | E18: 24 | F18: =E18-G18-I18 -> 24 | G18: 0 | H18: =E18-G18-I18-J18 -> 24 | I18: 0 | J18: 0 | K18: =E18-G18-L18-M18 -> 24 | L18: 0 | M18: 0 | O18: 56 | P18: ='Data Base Guru SD'!R15 -> S1 | Q18: ='Data Base Guru SD'!F15 -> 8 Tahun 6 Bulan 9 Hari | R18: 8 | S18: ='Data Base Guru SD'!G15 -> PT | T18: 1950000 | V18: ='Data Base Guru SD'!X15 -> 0 | W18: =V18*20000 -> 0 | X18: =T18+U18+W18 -> 1950000 | Z18: 150000 | AE18: =SUM(AA18:AD18) -> 0 | AF18: =F18*10000 -> 240000 | AG18: =H18*5000 -> 120000 | AH18: =K18*5000 -> 120000 | AI18: =O18*5000 -> 280000 | AJ18: 150000 | AK18: 0 | AL18: =SUM(Y18,Z18,AE18,AF18,AG18,AH18,AI18,AJ18) -> 1060000 | AM18: =X18+AL18 -> 3010000 | AN18: =AM18*AO18 -> 0 | AP18: =N18 -> 0 | AQ18: =AO18*AP18 -> 0 | AS18: 0 | AT18: A | AU18: =SUM(AN18,AQ18,AR18,AS18) -> 0 | AV18: =B18 -> Sri Rahayu, S.Pd | AW18: =AM18-AU18 -> 3010000
A19: 9 | B19: ='Data Base Guru SD'!B16 -> Susilawati, S.Pd | C19: ='Data Base Guru SD'!J16 -> Mapel (Mengaji ) | D19: =F19+I19 -> 24 | E19: 24 | F19: =E19-G19-I19 -> 24 | G19: 0 | H19: =E19-G19-I19-J19 -> 24 | I19: 0 | J19: 0 | K19: =E19-G19-L19-M19 -> 24 | L19: 0 | M19: 0 | O19: 40 | P19: ='Data Base Guru SD'!R16 -> S1 | Q19: ='Data Base Guru SD'!F16 -> 8 Tahun 5 Bulan 9 Hari | R19: 8 | S19: ='Data Base Guru SD'!G16 -> PT | T19: 1950000 | V19: ='Data Base Guru SD'!X16 -> 3 | W19: =V19*20000 -> 60000 | X19: =T19+U19+W19 -> 2010000 | Z19: 150000 | AE19: =SUM(AA19:AD19) -> 0 | AF19: =F19*10000 -> 240000 | AG19: =H19*5000 -> 120000 | AH19: =K19*5000 -> 120000 | AI19: =O19*5000 -> 200000 | AJ19: 150000 | AK19: 0 | AL19: =SUM(Y19,Z19,AE19,AF19,AG19,AH19,AI19,AJ19) -> 980000 | AM19: =X19+AL19 -> 2990000 | AN19: =AM19*AO19 -> 0 | AP19: =N19 -> 0 | AQ19: =AO19*AP19 -> 0 | AS19: 0 | AT19: A | AU19: =SUM(AN19,AQ19,AR19,AS19) -> 0 | AV19: =B19 -> Susilawati, S.Pd | AW19: =AM19-AU19 -> 2990000
A20: 10 | B20: ='Data Base Guru SD'!B17 -> Rismawati, S.Pd | C20: ='Data Base Guru SD'!J17 -> Wali Kelas ( Mengaji ) | D20: =F20+I20 -> 24 | E20: 24 | F20: =E20-G20-I20 -> 24 | G20: 0 | H20: =E20-G20-I20-J20 -> 24 | I20: 0 | J20: 0 | K20: =E20-G20-L20-M20 -> 24 | L20: 0 | M20: 0 | O20: 48 | P20: ='Data Base Guru SD'!R17 -> S1 | Q20: ='Data Base Guru SD'!F17 -> 8 Tahun 1 Bulan 9 Hari | R20: 8 | S20: ='Data Base Guru SD'!G17 -> PT | T20: 1950000 | V20: ='Data Base Guru SD'!X17 -> 0 | W20: =V20*20000 -> 0 | X20: =T20+U20+W20 -> 1950000 | Z20: 150000 | AA20: 100000 | AE20: =SUM(AA20:AD20) -> 100000 | AF20: =F20*10000 -> 240000 | AG20: =H20*5000 -> 120000 | AH20: =K20*5000 -> 120000 | AI20: =O20*5000 -> 240000 | AJ20: 150000 | AK20: 0 | AL20: =SUM(Y20,Z20,AE20,AF20,AG20,AH20,AI20,AJ20) -> 1120000 | AM20: =X20+AL20 -> 3070000 | AN20: =AM20*AO20 -> 0 | AP20: =N20 -> 0 | AQ20: =AO20*AP20 -> 0 | AS20: 0 | AT20: A | AU20: =SUM(AN20,AQ20,AR20,AS20) -> 0 | AV20: =B20 -> Rismawati, S.Pd | AW20: =AM20-AU20 -> 3070000
A21: 11 | B21: ='Data Base Guru SD'!B18 -> Ertika, S.Pd | C21: ='Data Base Guru SD'!J18 -> Wali Kelas ( Mengaji ) | D21: =F21+I21 -> 24 | E21: 24 | F21: =E21-G21-I21 -> 24 | G21: 0 | H21: =E21-G21-I21-J21 -> 24 | I21: 0 | J21: 0 | K21: =E21-G21-L21-M21 -> 24 | L21: 0 | M21: 0 | O21: 48 | P21: ='Data Base Guru SD'!R18 -> S1 | Q21: ='Data Base Guru SD'!F18 -> 8 Tahun 7 Bulan 9 Hari | R21: 8 | S21: ='Data Base Guru SD'!G18 -> PT | T21: 1950000 | V21: ='Data Base Guru SD'!X18 -> 2 | W21: =V21*20000 -> 40000 | X21: =T21+U21+W21 -> 1990000 | AA21: 100000 | AE21: =SUM(AA21:AD21) -> 100000 | AF21: =F21*10000 -> 240000 | AG21: =H21*5000 -> 120000 | AH21: =K21*5000 -> 120000 | AI21: =O21*5000 -> 240000 | AJ21: 150000 | AK21: 0 | AL21: =SUM(Y21,Z21,AE21,AF21,AG21,AH21,AI21,AJ21) -> 970000 | AM21: =X21+AL21 -> 2960000 | AN21: =AM21*AO21 -> 0 | AP21: =N21 -> 0 | AQ21: =AO21*AP21 -> 0 | AS21: 0 | AT21: A | AU21: =SUM(AN21,AQ21,AR21,AS21) -> 0 | AV21: =B21 -> Ertika, S.Pd | AW21: =AM21-AU21 -> 2960000
A22: 12 | B22: ='Data Base Guru SD'!B19 -> Kurniati, A.MA, Pd. OR | C22: ='Data Base Guru SD'!J19 -> Mapel | D22: =F22+I22 -> 24 | E22: 24 | F22: =E22-G22-I22 -> 24 | G22: 0 | H22: =E22-G22-I22-J22 -> 24 | I22: 0 | J22: 0 | K22: =E22-G22-L22-M22 -> 24 | L22: 0 | M22: 0 | O22: 56 | P22: ='Data Base Guru SD'!R19 -> S1 | Q22: ='Data Base Guru SD'!F19 -> 7 Tahun 10 Bulan 9 Hari | R22: 7 | S22: ='Data Base Guru SD'!G19 -> PT | T22: 1950000 | V22: ='Data Base Guru SD'!X19 -> 0 | W22: =V22*20000 -> 0 | X22: =T22+U22+W22 -> 1950000 | Z22: 150000 | AE22: =SUM(AA22:AD22) -> 0 | AF22: =F22*10000 -> 240000 | AG22: =H22*5000 -> 120000 | AH22: =K22*5000 -> 120000 | AI22: =O22*5000 -> 280000 | AJ22: 150000 | AK22: 0 | AL22: =SUM(Y22,Z22,AE22,AF22,AG22,AH22,AI22,AJ22) -> 1060000 | AM22: =X22+AL22 -> 3010000 | AN22: =AM22*AO22 -> 0 | AP22: =N22 -> 0 | AQ22: =AO22*AP22 -> 0 | AS22: 0 | AT22: A | AU22: =SUM(AN22,AQ22,AR22,AS22) -> 0 | AV22: =B22 -> Kurniati, A.MA, Pd. OR | AW22: =AM22-AU22 -> 3010000
A23: 13 | B23: ='Data Base Guru SD'!B20 -> Uppi Erniati H, S.Pd | C23: ='Data Base Guru SD'!J20 -> Wali Kelas | D23: =F23+I23 -> 24 | E23: 24 | F23: =E23-G23-I23 -> 24 | G23: 0 | H23: =E23-G23-I23-J23 -> 24 | I23: 0 | J23: 0 | K23: =E23-G23-L23-M23 -> 24 | L23: 0 | M23: 0 | O23: 0 | P23: ='Data Base Guru SD'!R20 -> S1 | Q23: ='Data Base Guru SD'!F20 -> 7 Tahun 7 Bulan 9 Hari | R23: 7 | S23: ='Data Base Guru SD'!G20 -> PT | T23: 1950000 | V23: ='Data Base Guru SD'!X20 -> 3 | W23: =V23*20000 -> 60000 | X23: =T23+U23+W23 -> 2010000 | Z23: 150000 | AA23: 100000 | AE23: =SUM(AA23:AD23) -> 100000 | AF23: =F23*10000 -> 240000 | AG23: =H23*5000 -> 120000 | AH23: =K23*5000 -> 120000 | AI23: =O23*5000 -> 0 | AJ23: 150000 | AK23: 0 | AL23: =SUM(Y23,Z23,AE23,AF23,AG23,AH23,AI23,AJ23) -> 880000 | AM23: =X23+AL23 -> 2890000 | AN23: =AM23*AO23 -> 0 | AP23: =N23 -> 0 | AQ23: =AO23*AP23 -> 0 | AS23: 0 | AT23: A | AU23: =SUM(AN23,AQ23,AR23,AS23) -> 0 | AV23: =B23 -> Uppi Erniati H, S.Pd | AW23: =AM23-AU23 -> 2890000
